Workbook

Sheet Metadata
B2: United States Department of the Interior
B3: U.S. Fish and Wildlife Service | E3: Report prepared for:
B4: Red Bluff Fish and Wildlife Office
B5: 10950 Tyler Road | E5: Customer: | F5: United States Bureau of Reclamation
B6: Red Bluff, CA 96080 | F6: Mid-Pacific Regional Office
E7: Customer Address: | F7: 2800 Cottage Way
B8: https://www.fws.gov/redbluff/ | E8: Customer City, State, Zip: | F8: Sacramento, CA 95825-1898
E9: Customer Phone: | F9: 916.978.4315
B10: Prepared by: | E10: Customer Email:
B11: Mike Schraml: 530.527.3043 / mike_schraml@fws.gov
A15: Table of Contents
A16: Metadata
A17: Contact Information
A18: Summary
A19: Use Limitations
A20: References
A21: Worksheet Descriptions
A22: Data Descriptions
A23: UCC CHN 23-24 worksheet
A24: LCC CHN 23-24 worksheet
A25: LCC RBT 23-24 worksheet
A26: LCC with UCC Fish worksheet
... A34: LCC Tables & Figures
A36: Summary: | B36: The data was collected by the U.S. Fish and Wildlife Service's, Red Bluff Fish and Wildlife Office's, Battle Creek Monitoring Program. The data encompasses the brood year (BY) 2017 and 2018 mark-recapture (M-R) data collected on Clear Creek, California, from December 7, 2017, through March 21, 2018, and December 27, 2016, through January 31, 2017. The catch data was collected using at 5-ft diameter rotary screw traps located at river mile 1.7, 40.506159N latitude, -122.396079W Longitude (lower Clear Creek, LCC) and at river mile 8.4, 40.491850N latitude, -122.496572W Longitude (decimal upper Clear Creek, UCC).
A37: Use Limitations: | B37: FWS assumes no liability for the improper or incorrect use of these data. These data are intended for the use of Clear Creek monitoring. The final data can be found in our monitoring reports at http://www.fws.gov/redbluff/cvpia.aspx.
A38: References: | B38: Bailey, N. T. J. 1951. On Estimating the Size of Mobile Populations from Recapture Data. Biometrika 38(3):293-306.
B39: Buckland, S. T., and P. H. Garthwaite. 1991. Quantifying Precision of Mark-Recapture Estimates Using the Bootstrap and Related Methods. Biometrics 47(1):255-268.
B40: Carlson, S. R., L. G. Coggins Jr, and C. O. Swanton. 1998. A simple stratified design for mark-recapture estimation of salmon smolt abundance. Alaska Fishery Research Bulletin 5(2):88-102.
B41: Thedinga, J. F., M. L. Murphy, S. W. Johnson, J. M. Lorenz, and K. V. Koski. 1994. Determination of salmonid smolt yield with rotary-screw traps in the Situk River, Alaska, to predict effects of glacial flooding. North American Journal of Fisheries Management 14(4):837-851.
A42: Return to Table of Contents
A43: Excel Worksheet Name | B43: Worksheet Description
A44: UCC CHN 23-24 | B44: This worksheet contains the M-R trial data and results obtained during the brood year 2018 spring-run Chinook Salmon sampling season conducted at the UCC trap during the December 27, 2016, through January 31, 2017, time period. The Bailey's efficiency calculated on this worksheet is used to generate the passage indices (estimated) for the annual report.
A45: LCC CHN 23-24 | B45: This worksheet contains the M-R trial data and results obtained during the brood year 2018 Chinook Salmon sampling season conducted at the LCC trap during the December 27, 2016, through January 31, 2017, time period. The Bailey's efficiency calculated on this worksheet is used to generate the passage indices (estimated) for the annual report.
A46: LCC RBT 23-24 | B46: This worksheet contains the M-R trial data and results obtained during the brood year 2018 Rainbow Trout/steelhead sampling season conducted at the LCC trap during the December 27, 2016, through January 31, 2017, time period.
A47: LCC with UCC Fish | B47: This worksheet contains the M-R trial data and results obtained during the brood year 2018 spring-run Chinook Salmon sampling season conducted at the UCC trap during the December 27, 2016, through January 31, 2017, time period. It represents the number of marked fish released upstream of the UCC trap and recaptured in the LCC trap.
A48: UCC Tables & Figures | B48: This worksheet contains the table and figures presented in the report.
A49: LCC Tables & Figures | B49: This worksheet contains the table and figures presented in the report.
A50: Data Descriptions
A51: UCC CHN 23-24 worksheet | B51: Column Name | C51: Column | D51: Data Description | K51: Unit | L51: Spreadsheet Origin | M51: Worksheet Origin
A52: Return to Table of Contents | B52: Trial | C52: A | D52: The trial number for BY 2018 Chinook Salmon M-R sampling at the UCC trap. | K52: N/A | L52: N/A | M52: N/A
...

Sheet Issues
A1: Tab | B1: Problem | C1: Noticed by | D1: Date Noticed | E1: Fixed by | F1: Date Fixed | G1: Notes

Sheet UCC CHN 25-26
A1: Upper Clear Creek CHN 2025-2026 | I1: Do not enter data into blue shaded cells | AB1: Upper Clear Creek Chinook Salmon
A2: Trial | B2: Mark date | C2: Release date | D2: Days held | E2: Number held | F2: Number marked | G2: Number released | H2: Pre-mark mortalities | I2: Marking mortalities | J2: Post-mark mortalities | K2: Predation / Trap mortalities | L2: Total mortalities | M2: Percent mortality | N2: Number caught day 1 | O2: Percent caught day 1 | P2: Number caught day 2 | Q2: Percent caught day 2 | R2: Number caught day 3 | S2: Percent caught day 3 | T2: Number caught day 4 | U2: Percent caught day 4 | V2: Total live recaptures | W2: Total recaptured | X2: Bailey's efficiency | Y2: Race | Z2: Origin | AB2: Mark type | AC2: Mark date | AD2: Release date | AE2: Days held | AF2: Number held | AG2: Number marked | AH2: Number released | AI2: Pre-mark mortalities | AJ2: Marking mortalities | AK2: Post-mark mortalities | AL2: Percent mortality | AM2: Number live caught day 1 | AN2: Number mortalities caught day 1 | AO2: Percent caught day 1 | AP2: Number live caught day 2 | AQ2: Number mortalities caught day 2 | AR2: Percent caught day 2 | AS2: Number live caught day 3 | AT2: Number mortalities caught day 3 | AU2: Percent caught day 3 | AV2: Number live caught day 4 | AW2: Number mortalities caught day 4 | AX2: Percent caught day 4 | AY2: Total live recaptured | AZ2: Total mortalities recaptured | BA2: Total recaptured | BB2: Bailey's efficiency | BC2: Race | BD2: Origin
A3: 1 | B3: 45982 | C3: 45983 | D3: 1 | E3: =AF7 -> 74 | F3: =AG7 -> 73 | G3: =AH7 -> 73 | H3: =AI7 -> 1 | I3: =AJ7 -> 0 | J3: =AK7 -> 0 | K3: =AZ7 -> 0 | L3: =SUM(H3:K3) -> 1 | M3: =L3/E3 -> 0.013513514 | N3: =AM7+AN7 -> 10 | O3: =N3/G3 -> 0.1369863 | P3: =SUM(AP7:AQ7) -> 2 | Q3: =P3/G3 -> 0.02739726 | R3: =SUM(AS7:AT7) -> 0 | S3: =R3/G3 -> 0 | T3: =SUM(AV7:AW7) -> 0 | U3: =T3/G3 -> 0 | V3: =AX7 -> 0 | W3: =BA7 -> 12 | X3: =(W3+1)/(G3+1) -> 0.17567568 | Y3: SCS | Z3: U+LCC | AB3: Trial 1
A4: 2 | B4: 45989 | C4: 45990 | D4: 1 | E4: =AF12 -> 506 | F4: =AG12 -> 240 | G4: =AH12 -> 238 | H4: =AI12 -> 2 | I4: =AJ12 -> 0 | J4: =AK12 -> 2 | K4: =AZ12 -> 1 | L4: =SUM(H4:K4) -> 5 | M4: =L4/E4 -> 0.0098814229 | N4: =AM12+AN12 -> 58 | O4: =N4/G4 -> 0.24369748 | P4: =SUM(AO12:AP12) -> 4 | Q4: =P4/G4 -> 0.016806723 | R4: =SUM(AR12:AS12) -> 0 | S4: =R4/G4 -> 0 | T4: =SUM(AU12:AV12) -> 0 | U4: =T4/G4 -> 0 | V4: =AX12 -> 0 | W4: =BA12 -> 62 | X4: =(W4+1)/(G4+1) -> 0.26359833 | Y4: SCS | Z4: U+LCC | AB4: No clip | AL4: =SUM(AI4:AK4)/AG4 -> #DIV/0! | AO4: =SUM(AM4:AN4)/AH4 -> #DIV/0! | AR4: =(AP4+AQ4)/$AH4 -> #DIV/0! | AU4: =(AS4+AT4)/$AH4 -> #DIV/0! | AX4: =(AV4+AW4)/$AH4 -> #DIV/0! | AY4: =SUM(AM4,AP4,AS4,AV4) -> 0 | AZ4: =SUM(AN4,AQ4,AT4,AW4) -> 0 | BA4: =SUM(AY4:AZ4) -> 0 | BB4: =(BA4+1)/(AH4+1) -> 1
A5: 3 | B5: 45993 | C5: 45994 | D5: 1 | E5: =AF17 -> 608 | F5: =AG17 -> 335 | G5: =AH17 -> 335 | H5: =AI17 -> 2 | I5: =AJ17 -> 0 | J5: =AK17 -> 0 | K5: =AZ17 -> 1 | L5: =SUM(H5:K5) -> 3 | M5: =L5/E5 -> 0.0049342105 | N5: =AM17+AN17 -> 76 | O5: =N5/G5 -> 0.22686567 | P5: =SUM(AO17:AP17) -> 3 | Q5: =P5/G5 -> 0.0089552239 | R5: =SUM(AR17:AS17) -> 0 | S5: =R5/G5 -> 0 | T5: =SUM(AU17:AV17) -> 0 | U5: =T5/G5 -> 0 | V5: =AX17 -> 0 | W5: =BA17 -> 80 | X5: =(W5+1)/(G5+1) -> 0.24107143 | Y5: SCS | Z5: UCC | AB5: Lower clip | AL5: =SUM(AI5:AK5)/AG5 -> #DIV/0! | AO5: =SUM(AM5:AN5)/AH5 -> #DIV/0! | AR5: =(AP5+AQ5)/$AH5 -> #DIV/0! | AU5: =(AS5+AT5)/$AH5 -> #DIV/0! | AX5: =(AV5+AW5)/$AH5 -> #DIV/0! | AY5: =SUM(AM5,AP5,AS5,AV5) -> 0 | AZ5: =SUM(AN5,AQ5,AT5,AW5) -> 0 | BA5: =SUM(AY5:AZ5) -> 0 | BB5: =(BA5+1)/(AH5+1) -> 1
A6: 4 | B6: 45996 | C6: 45997 | D6: 1 | E6: =AF22 -> 1030 | F6: =AG22 -> 501 | G6: =AH22 -> 497 | H6: =AI22 -> 3 | I6: =AJ22 -> 1 | J6: =AK22 -> 1 | K6: =AZ22 -> 2 | L6: =SUM(H6:K6) -> 7 | M6: =L6/E6 -> 0.0067961165 | N6: =AL22+AM22 -> 162 | O6: =N6/G6 -> 0.32595573 | P6: =SUM(AO22:AP22) -> 6 | Q6: =P6/G6 -> 0.012072435 | R6: =SUM(AR22:AS22) -> 0 | S6: =R6/G6 -> 0 | T6: =SUM(AU22:AV22) -> 0 | U6: =T6/G6 -> 0 | V6: =AX22 -> 0 | W6: =BA22 -> 170 | X6: =(W6+1)/(G6+1) -> 0.34337349 | Y6: SCS | Z6: U+LCC | AB6: Upper clip | AC6: 45982 | AD6: 45983 | AE6: 1 | AF6: 74 | AG6: 73 | AH6: 73 | AI6: 1 | AJ6: 0 | AL6: =SUM(AI6:AK6)/AG6 -> 0.01369863 | AM6: 10 | AN6: 0 | AO6: =SUM(AM6:AN6)/AH6 -> 0.1369863 | AP6: 2 | AQ6: 0 | AR6: =(AP6+AQ6)/$AH6 -> 0.02739726 | AS6: 0 | AT6: 0 | AU6: =(AS6+AT6)/$AH6 -> 0 | AV6: 0 | AW6: 0 | AX6: =(AV6+AW6)/$AH6 -> 0 | AY6: =SUM(AM6,AP6,AS6,AV6) -> 12 | AZ6: =SUM(AN6,AQ6,AT6,AW6) -> 0 | BA6: =SUM(AY6:AZ6) -> 12 | BB6: =(BA6+1)/(AH6+1) -> 0.17567568 | BC6: SRC | BD6: UCC LCC
A7: 5 | B7: 46000 | C7: 46001 | D7: 1 | E7: =AF27 -> 457 | F7: =AG27 -> 448 | G7: =AH27 -> 447 | H7: =AI27 -> 3 | I7: =AJ27 -> 0 | J7: =AK27 -> 0 | K7: =AZ27 -> 0 | L7: =SUM(H7:K7) -> 3 | M7: =L7/E7 -> 0.0065645514 | N7: =AL27+AM27 -> 136 | O7: =N7/G7 -> 0.30425056 | P7: =SUM(AO27:AP27) -> 11 | Q7: =P7/G7 -> 0.024608501 | R7: =SUM(AR27:AS27) -> 9 | S7: =R7/G7 -> 0.020134228 | T7: =SUM(AU27:AV27) -> 0 | U7: =T7/G7 -> 0 | V7: =AX27 -> 0 | W7: =BA27 -> 156 | X7: =(W7+1)/(G7+1) -> 0.35044643 | Y7: SCS | Z7: U+LCC | AF7: =SUM(AF4:AF6) -> 74 | AG7: =SUM(AG4:AG6) -> 73 | AH7: =SUM(AH4:AH6) -> 73 | AI7: =SUM(AI4:AI6) -> 1 | AJ7: =SUM(AJ4:AJ6) -> 0 | AK7: =SUM(AK4:AK6) -> 0 | AM7: =SUM(AM4:AM6) -> 10 | AN7: =SUM(AN4:AN6) -> 0 | AP7: =SUM(AP4:AP6) -> 2 | AQ7: =SUM(AQ4:AQ6) -> 0 | AS7: =SUM(AS4:AS6) -> 0 | AT7: =SUM(AT4:AT6) -> 0 | AV7: =SUM(AV4:AV6) -> 0 | AW7: =SUM(AW4:AW6) -> 0 | AY7: =SUM(AY4:AY6) -> 12 | AZ7: =SUM(AZ4:AZ6) -> 0 | BA7: =SUM(AY7:AZ7) -> 12 | BB7: =(BA7+1)/(AH7+1) -> 0.17567568
A8: 6 | B8: 46003 | C8: 46004 | D8: 1 | E8: =AF32 -> 439 | F8: =AG32 -> 438 | G8: =AH32 -> 437 | H8: =AI32 -> 0 | I8: =AJ32 -> 0 | J8: =AK32 -> 1 | K8: =AZ32 -> 0 | L8: =SUM(H8:K8) -> 1 | M8: =L8/E8 -> 0.0022779043 | N8: =AL32+AM32 -> 115 | O8: =N8/G8 -> 0.26315789 | P8: =SUM(AO32:AP32) -> 6 | Q8: =P8/G8 -> 0.013729977 | R8: =SUM(AR32:AS32) -> 1 | S8: =R8/G8 -> 0.0022883295 | T8: =SUM(AU32:AV32) -> 0 | U8: =T8/G8 -> 0 | V8: =AX32 -> 0 | W8: =BA32 -> 122 | X8: =(W8+1)/(G8+1) -> 0.28082192 | Y8: SCS | AB8: Trial 2
A9: 7 | B9: 46038 | C9: 46039 | D9: 1 | E9: =AF37 -> 509 | F9: =AG37 -> 504 | G9: =AH37 -> 503 | H9: =AI37 -> 0 | I9: =AJ37 -> 0 | J9: =AK37 -> 0 | K9: =AZ37 -> 2 | L9: =SUM(H9:K9) -> 2 | M9: =L9/E9 -> 0.0039292731 | N9: =AL37+AM37 -> 54 | O9: =N9/G9 -> 0.10735586 | P9: =SUM(AO37:AP37) -> 0 | Q9: =P9/G9 -> 0 | R9: =SUM(AR37:AS37) -> 0 | S9: =R9/G9 -> 0 | T9: =SUM(AU37:AV37) -> 0 | U9: =T9/G9 -> 0 | V9: =AX37 -> 0 | W9: =BA37 -> 56 | X9: =(W9+1)/(G9+1) -> 0.11309524 | Y9: SCS | Z9: LCC | AB9: No clip | AL9: =SUM(AI9:AK9)/AG9 -> #DIV/0! | AO9: =SUM(AM9:AN9)/AH9 -> #DIV/0! | AR9: =(AP9+AQ9)/$AH9 -> #DIV/0! | AU9: =(AS9+AT9)/$AH9 -> #DIV/0! | AX9: =(AV9+AW9)/$AH9 -> #DIV/0! | AY9: =SUM(AM9,AP9,AS9,AV9) -> 0 | AZ9: =SUM(AN9,AQ9,AT9,AW9) -> 0 | BA9: =SUM(AY9:AZ9) -> 0 | BB9: =(BA9+1)/(AH9+1) -> 1
A10: 8 | B10: 46042 | C10: 46043 | D10: 1 | E10: =AF42 -> 545 | F10: =AG42 -> 541 | G10: =AH42 -> 535 | H10: =AI42 -> 0 | I10: =AJ42 -> 0 | J10: =AK42 -> 0 | K10: =AZ42 -> 0 | L10: =SUM(H10:K10) -> 0 | M10: =L10/E10 -> 0 | N10: =AL42+AM42 -> 89 | O10: =N10/G10 -> 0.16635514 | P10: =SUM(AO42:AP42) -> 4 | Q10: =P10/G10 -> 0.0074766355 | R10: =SUM(AR42:AS42) -> 1 | S10: =R10/G10 -> 0.0018691589 | T10: =SUM(AU42:AV42) -> 0 | U10: =T10/G10 -> 0 | V10: =AX42 -> 0 | W10: =BA42 -> 94 | X10: =(W10+1)/(G10+1) -> 0.17723881 | Y10: SCS | Z10: LCC | AB10: Lower clip | AL10: =SUM(AI10:AK10)/AG10 -> #DIV/0! | AO10: =SUM(AM10:AN10)/AH10 -> #DIV/0! | AR10: =(AP10+AQ10)/$AH10 -> #DIV/0! | AU10: =(AS10+AT10)/$AH10 -> #DIV/0! | AX10: =(AV10+AW10)/$AH10 -> #DIV/0! | AY10: =SUM(AM10,AP10,AS10,AV10) -> 0 | AZ10: =SUM(AN10,AQ10,AT10,AW10) -> 0 | BA10: =SUM(AY10:AZ10) -> 0 | BB10: =(BA10+1)/(AH10+1) -> 1
A11: 9 | B11: 46045 | C11: 46046 | D11: 1 | E11: =AF47 -> 1028 | F11: =AG47 -> 510 | G11: =AH47 -> 508 | H11: =AI47 -> 0 | I11: =AJ47 -> 3 | J11: =AK47 -> 2 | K11: =AZ47 -> 1 | L11: =SUM(H11:K11) -> 6 | M11: =L11/E11 -> 0.0058365759 | N11: =AL47+AM47 -> 76 | O11: =N11/G11 -> 0.1496063 | P11: =SUM(AO47:AP47) -> 15 | Q11: =P11/G11 -> 0.029527559 | R11: =SUM(AR47:AS47) -> 2 | S11: =R11/G11 -> 0.0039370079 | T11: =SUM(AU47:AV47) -> 0 | U11: =T11/G11 -> 0 | V11: =AX47 -> 0 | W11: =BA47 -> 94 | X11: =(W11+1)/(G11+1) -> 0.18664047 | Y11: FCS | Z11: LCC | AB11: Upper clip | AC11: 45989 | AD11: 45990 | AE11: 1 | AF11: 506 | AG11: 240 | AH11: 238 | AI11: 2 | AJ11: 0 | AK11: 2 | AL11: =SUM(AI11:AK11)/AG11 -> 0.016666667 | AM11: 57 | AN11: 1 | AO11: =SUM(AM11:AN11)/AH11 -> 0.24369748 | AP11: 4 | AQ11: 0 | AR11: =(AP11+AQ11)/$AH11 -> 0.016806723 | AS11: 0 | AT11: 0 | AU11: =(AS11+AT11)/$AH11 -> 0 | AV11: 0 | AW11: 0 | AX11: =(AV11+AW11)/$AH11 -> 0 | AY11: =SUM(AM11,AP11,AS11,AV11) -> 61 | AZ11: =SUM(AN11,AQ11,AT11,AW11) -> 1 | BA11: =SUM(AY11:AZ11) -> 62 | BB11: =(BA11+1)/(AH11+1) -> 0.26359833 | BC11: SRS | BD11: UCC LCC
A12: 10 | B12: 46052 | C12: 46053 | D12: 1 | E12: =AF52 -> 477 | F12: =AG52 -> 477 | G12: =AH52 -> 476 | H12: =AI52 -> 0 | I12: =AJ52 -> 1 | J12: =AK52 -> 0 | K12: =AZ52 -> 1 | L12: =SUM(H12:K12) -> 2 | M12: =L12/E12 -> 0.0041928721 | N12: =AL52+AM52 -> 96 | O12: =N12/G12 -> 0.20168067 | P12: =SUM(AO52:AP52) -> 5 | Q12: =P12/G12 -> 0.010504202 | R12: =SUM(AR52:AS52) -> 0 | S12: =R12/G12 -> 0 | T12: =SUM(AU52:AV52) -> 1 | U12: =T12/G12 -> 0.0021008403 | V12: =AX52 -> 0 | W12: =BA52 -> 103 | X12: =(W12+1)/(G12+1) -> 0.21802935 | Y12: FCS | Z12: LCC | AF12: =SUM(AF9:AF11) -> 506 | AG12: =SUM(AG9:AG11) -> 240 | AH12: =SUM(AH9:AH11) -> 238 | AI12: =SUM(AI9:AI11) -> 2 | AJ12: =SUM(AJ9:AJ11) -> 0 | AK12: =SUM(AK9:AK11) -> 2 | AM12: =SUM(AM9:AM11) -> 57 | AN12: =SUM(AN9:AN11) -> 1 | AP12: =SUM(AP9:AP11) -> 4 | AQ12: =SUM(AQ9:AQ11) -> 0 | AS12: =SUM(AS9:AS11) -> 0 | AT12: =SUM(AT9:AT11) -> 0 | AV12: =SUM(AV9:AV11) -> 0 | AW12: =SUM(AW9:AW11) -> 0 | AY12: =SUM(AY9:AY11) -> 61 | AZ12: =SUM(AZ9:AZ11) -> 1 | BA12: =SUM(AY12:AZ12) -> 62 | BB12: =(BA12+1)/(AH12+1) -> 0.26359833
A13: 11 | B13: 46056 | C13: 46057 | D13: 1 | E13: =AF56 -> 500 | F13: 499 | G13: =AH57 -> 497 | H13: =AI57 -> 1 | I13: =AJ57 -> 0 | J13: =AK57 -> 2 | K13: =AZ57 -> 0 | L13: =SUM(H13:K13) -> 3 | M13: =L13/E13 -> 0.006 | N13: =AL57+AM57 -> 106 | O13: =N13/G13 -> 0.21327968 | P13: =SUM(AO57:AP57) -> 2 | Q13: =P13/G13 -> 0.0040241449 | R13: =SUM(AR57:AS57) -> 0 | S13: =R13/G13 -> 0 | T13: =SUM(AU57:AV57) -> 0 | U13: =T13/G13 -> 0 | V13: =AX57 -> 0 | W13: =BA57 -> 108 | X13: =(W13+1)/(G13+1) -> 0.2188755 | Y13: FCS | Z13: LCC | AB13: Trial 3
A14: 12 | B14: 46059 | C14: 46060 | D14: 1 | E14: 502 | F14: 496 | G14: 496 | H14: =AI62 -> 3 | I14: 0 | J14: 0 | K14: =AZ62 -> 0 | L14: =SUM(H14:K14) -> 3 | M14: =L14/E14 -> 0.0059760956 | N14: 69 | O14: =N14/G14 -> 0.1391129 | P14: 0 | Q14: =P14/G14 -> 0 | R14: =SUM(AR62:AS62) -> 1 | S14: =R14/G14 -> 0.002016129 | T14: =SUM(AU62:AV62) -> 0 | U14: =T14/G14 -> 0 | V14: =AX62 -> 0 | W14: =BA62 -> 72 | X14: =(W14+1)/(G14+1) -> 0.14688129 | Y14: FCS | Z14: LCC | AB14: No clip | AL14: =SUM(AI14:AK14)/AG14 -> #DIV/0! | AO14: =SUM(AM14:AN14)/AH14 -> #DIV/0! | AR14: =(AP14+AQ14)/$AH14 -> #DIV/0! | AU14: =(AS14+AT14)/$AH14 -> #DIV/0! | AX14: =(AV14+AW14)/$AH14 -> #DIV/0! | AY14: =SUM(AM14,AP14,AS14,AV14) -> 0 | AZ14: =SUM(AN14,AQ14,AT14,AW14) -> 0 | BA14: =SUM(AY14:AZ14) -> 0 | BB14: =(BA14+1)/(AH14+1) -> 1
A15: 13 | E15: =AF67 -> 0 | F15: =AG67 -> 0 | G15: =AH67 -> 0 | H15: =AI67 -> 0 | I15: =AJ67 -> 0 | J15: =AK67 -> 0 | K15: =AZ67 -> 0 | L15: =SUM(H15:K15) -> 0 | M15: =L15/E15 -> #DIV/0! | N15: =AL67+AM67 -> 0 | O15: =N15/G15 -> #DIV/0! | P15: =SUM(AO67:AP67) -> 0 | Q15: =P15/G15 -> #DIV/0! | R15: =SUM(AR67:AS67) -> 0 | S15: =R15/G15 -> #DIV/0! | T15: =SUM(AU67:AV67) -> 0 | U15: =T15/G15 -> #DIV/0! | V15: =AX67 -> 0 | W15: =BA67 -> 0 | X15: =(W15+1)/(G15+1) -> 1 | AB15: Lower clip | AL15: =SUM(AI15:AK15)/AG15 -> #DIV/0! | AO15: =SUM(AM15:AN15)/AH15 -> #DIV/0! | AR15: =(AP15+AQ15)/$AH15 -> #DIV/0! | AU15: =(AS15+AT15)/$AH15 -> #DIV/0! | AX15: =(AV15+AW15)/$AH15 -> #DIV/0! | AY15: =SUM(AM15,AP15,AS15,AV15) -> 0 | AZ15: =SUM(AN15,AQ15,AT15,AW15) -> 0 | BA15: =SUM(AY15:AZ15) -> 0 | BB15: =(BA15+1)/(AH15+1) -> 1
A16: 14 | E16: =AF72 -> 0 | F16: =AG72 -> 0 | G16: =AH72 -> 0 | H16: =AI72 -> 0 | I16: =AJ72 -> 0 | J16: =AK72 -> 0 | K16: =AZ72 -> 0 | L16: =SUM(H16:K16) -> 0 | M16: =L16/E16 -> #DIV/0! | N16: =AL72+AM72 -> 0 | O16: =N16/G16 -> #DIV/0! | P16: =SUM(AO72:AP72) -> 0 | Q16: =P16/G16 -> #DIV/0! | R16: =SUM(AR72:AS72) -> 0 | S16: =R16/G16 -> #DIV/0! | T16: =SUM(AU72:AV72) -> 0 | U16: =T16/G16 -> #DIV/0! | V16: =AX72 -> 0 | W16: =BA72 -> 0 | X16: =(W16+1)/(G16+1) -> 1 | AB16: Upper clip | AC16: 45993 | AD16: 45994 | AE16: 1 | AF16: 608 | AG16: 335 | AH16: 335 | AI16: 2 | AJ16: 0 | AK16: 0 | AL16: =SUM(AI16:AK16)/AG16 -> 0.0059701493 | AM16: 76 | AN16: 0 | AO16: =SUM(AM16:AN16)/AH16 -> 0.22686567 | AP16: 3 | AQ16: 1 | AR16: =(AP16+AQ16)/$AH16 -> 0.011940299 | AS16: 0 | AT16: 0 | AU16: =(AS16+AT16)/$AH16 -> 0 | AV16: 0 | AW16: 0 | AX16: =(AV16+AW16)/$AH16 -> 0 | AY16: =SUM(AM16,AP16,AS16,AV16) -> 79 | AZ16: =SUM(AN16,AQ16,AT16,AW16) -> 1 | BA16: =SUM(AY16:AZ16) -> 80 | BB16: =(BA16+1)/(AH16+1) -> 0.24107143 | BC16: SRS | BD16: UCC
A17: 15 | E17: =AF77 -> 0 | F17: =AG77 -> 0 | G17: =AH77 -> 0 | H17: =AI77 -> 0 | I17: =AJ77 -> 0 | J17: =AK77 -> 0 | K17: =AZ77 -> 0 | L17: =SUM(H17:K17) -> 0 | M17: =L17/E17 -> #DIV/0! | N17: =AL77+AM77 -> 0 | O17: =N17/G17 -> #DIV/0! | P17: =SUM(AO77:AP77) -> 0 | Q17: =P17/G17 -> #DIV/0! | R17: =SUM(AR77:AS77) -> 0 | S17: =R17/G17 -> #DIV/0! | T17: =SUM(AU77:AV77) -> 0 | U17: =T17/G17 -> #DIV/0! | V17: =AX77 -> 0 | W17: =BA77 -> 0 | X17: =(W17+1)/(G17+1) -> 1 | AF17: =SUM(AF14:AF16) -> 608 | AG17: =SUM(AG14:AG16) -> 335 | AH17: =SUM(AH14:AH16) -> 335 | AI17: =SUM(AI14:AI16) -> 2 | AJ17: =SUM(AJ14:AJ16) -> 0 | AK17: =SUM(AK14:AK16) -> 0 | AM17: =SUM(AM14:AM16) -> 76 | AN17: =SUM(AN14:AN16) -> 0 | AP17: =SUM(AP14:AP16) -> 3 | AQ17: =SUM(AQ14:AQ16) -> 1 | AS17: =SUM(AS14:AS16) -> 0 | AT17: =SUM(AT14:AT16) -> 0 | AV17: =SUM(AV14:AV16) -> 0 | AW17: =SUM(AW14:AW16) -> 0 | AY17: =SUM(AY14:AY16) -> 79 | AZ17: =SUM(AZ14:AZ16) -> 1 | BA17: =SUM(AY17:AZ17) -> 80 | BB17: =(BA17+1)/(AH17+1) -> 0.24107143
A18: 16 | E18: =AF82 -> 0 | F18: =AG82 -> 0 | G18: =AH82 -> 0 | H18: =AI82 -> 0 | I18: =AJ82 -> 0 | J18: =AK82 -> 0 | K18: =AZ82 -> 0 | L18: =SUM(H18:K18) -> 0 | M18: =L18/E18 -> #DIV/0! | N18: =AL82+AM82 -> 0 | O18: =N18/G18 -> #DIV/0! | P18: =SUM(AO82:AP82) -> 0 | Q18: =P18/G18 -> #DIV/0! | R18: =SUM(AR82:AS82) -> 0 | S18: =R18/G18 -> #DIV/0! | T18: =SUM(AU82:AV82) -> 0 | U18: =T18/G18 -> #DIV/0! | V18: =AX82 -> 0 | W18: =BA82 -> 0 | X18: =(W18+1)/(G18+1) -> 1 | AB18: Trial 4
A19: 17 | E19: =AF87 -> 0 | F19: =AG87 -> 0 | G19: =AH87 -> 0 | H19: =AI87 -> 0 | I19: =AJ87 -> 0 | J19: =AK887 -> 0 | K19: =AZ87 -> 0 | L19: =SUM(H19:K19) -> 0 | M19: =L19/E19 -> #DIV/0! | N19: =AL87+AM87 -> 0 | O19: =N19/G19 -> #DIV/0! | P19: =SUM(AO87:AP87) -> 0 | Q19: =P19/G19 -> #DIV/0! | R19: =SUM(AR87:AS87) -> 0 | S19: =R19/G19 -> #DIV/0! | T19: =SUM(AU87:AV87) -> 0 | U19: =T19/G19 -> #DIV/0! | V19: =AX87 -> 0 | W19: =BA87 -> 0 | X19: =(W19+1)/(G19+1) -> 1 | AB19: No clip | AL19: =SUM(AI19:AK19)/AG19 -> #DIV/0! | AO19: =SUM(AM19:AN19)/AH19 -> #DIV/0! | AR19: =(AP19+AQ19)/$AH19 -> #DIV/0! | AU19: =(AS19+AT19)/$AH19 -> #DIV/0! | AX19: =(AV19+AW19)/$AH19 -> #DIV/0! | AY19: =SUM(AM19,AP19,AS19,AV19) -> 0 | AZ19: =SUM(AN19,AQ19,AT19,AW19) -> 0 | BA19: =SUM(AY19:AZ19) -> 0 | BB19: =(BA19+1)/(AH19+1) -> 1
A20: 18 | E20: =AF92 -> 0 | F20: =AG92 -> 0 | G20: =AH92 -> 0 | H20: =AI92 -> 0 | I20: =AJ92 -> 0 | J20: =AK92 -> 0 | K20: =AZ92 -> 0 | L20: =SUM(H20:K20) -> 0 | M20: =L20/E20 -> #DIV/0! | N20: =AL92+AM92 -> 0 | O20: =N20/G20 -> #DIV/0! | P20: =SUM(AO92:AP92) -> 0 | Q20: =P20/G20 -> #DIV/0! | R20: =SUM(AR92:AS92) -> 0 | S20: =R20/G20 -> #DIV/0! | T20: =SUM(AU92:AV92) -> 0 | U20: =T20/G20 -> #DIV/0! | V20: =AX92 -> 0 | W20: =BA92 -> 0 | X20: =(W20+1)/(G20+1) -> 1 | AB20: Lower clip | AL20: =SUM(AI20:AK20)/AG20 -> #DIV/0! | AO20: =SUM(AM20:AN20)/AH20 -> #DIV/0! | AR20: =(AP20+AQ20)/$AH20 -> #DIV/0! | AU20: =(AS20+AT20)/$AH20 -> #DIV/0! | AX20: =(AV20+AW20)/$AH20 -> #DIV/0! | AY20: =SUM(AM20,AP20,AS20,AV20) -> 0 | AZ20: =SUM(AN20,AQ20,AT20,AW20) -> 0 | BA20: =SUM(AY20:AZ20) -> 0 | BB20: =(BA20+1)/(AH20+1) -> 1
A21: 19 | E21: =AF97 -> 0 | F21: =AG97 -> 0 | G21: =AH97 -> 0 | H21: =AI97 -> 0 | I21: =AJ97 -> 0 | J21: =AK97 -> 0 | K21: =AZ97 -> 0 | L21: =SUM(H21:K21) -> 0 | M21: =L21/E21 -> #DIV/0! | N21: =AL97+AM97 -> 0 | O21: =N21/G21 -> #DIV/0! | P21: =SUM(AO97:AP97) -> 0 | Q21: =P21/G21 -> #DIV/0! | R21: =SUM(AR97:AS97) -> 0 | S21: =R21/G21 -> #DIV/0! | T21: =SUM(AU97:AV97) -> 0 | U21: =T21/G21 -> #DIV/0! | V21: =AX97 -> 0 | W21: =AB97 -> 0 | X21: =(W21+1)/(G21+1) -> 1 | AB21: Upper clip | AC21: 45996 | AD21: 45997 | AE21: 1 | AF21: 1030 | AG21: 501 | AH21: 497 | AI21: 3 | AJ21: 1 | AK21: 1 | AL21: =SUM(AI21:AK21)/AG21 -> 0.0099800399 | AM21: 162 | AN21: 1 | AO21: =SUM(AM21:AN21)/AH21 -> 0.32796781 | AP21: 6 | AQ21: 0 | AR21: =(AP21+AQ21)/$AH21 -> 0.012072435 | AS21: 0 | AT21: 1 | AU21: =(AS21+AT21)/$AH21 -> 0.0020120724 | AX21: =(AV21+AW21)/$AH21 -> 0 | AY21: =SUM(AM21,AP21,AS21,AV21) -> 168 | AZ21: =SUM(AN21,AQ21,AT21,AW21) -> 2 | BA21: =SUM(AY21:AZ21) -> 170 | BB21: =(BA21+1)/(AH21+1) -> 0.34337349
A22: 20 | E22: =AF102 -> 0 | F22: =AG102 -> 0 | G22: =AH102 -> 0 | H22: =AI102 -> 0 | I22: =AJ102 -> 0 | J22: =AK102 -> 0 | K22: =AZ102 -> 0 | L22: =SUM(H22:K22) -> 0 | M22: =L22/E22 -> #DIV/0! | N22: =AL102+AM102 -> 0 | O22: =N22/G22 -> #DIV/0! | P22: =SUM(AO102:AP102) -> 0 | Q22: =P22/G22 -> #DIV/0! | R22: =SUM(AR102:AS102) -> 0 | S22: =R22/G22 -> #DIV/0! | T22: =SUM(AU102:AV102) -> 0 | U22: =T22/G22 -> #DIV/0! | V22: =AX102 -> 0 | W22: =BA102 -> 0 | X22: =(W22+1)/(G22+1) -> 1 | AF22: =SUM(AF19:AF21) -> 1030 | AG22: =SUM(AG19:AG21) -> 501 | AH22: =SUM(AH19:AH21) -> 497 | AI22: =SUM(AI19:AI21) -> 3 | AJ22: =SUM(AJ19:AJ21) -> 1 | AK22: =SUM(AK19:AK21) -> 1 | AM22: =SUM(AM19:AM21) -> 162 | AN22: =SUM(AN19:AN21) -> 1 | AP22: =SUM(AP19:AP21) -> 6 | AQ22: =SUM(AQ19:AQ21) -> 0 | AS22: =SUM(AS19:AS21) -> 0 | AT22: =SUM(AT19:AT21) -> 1 | AV22: =SUM(AV19:AV21) -> 0 | AW22: =SUM(AW19:AW21) -> 0 | AY22: =SUM(AY19:AY21) -> 168 | AZ22: =SUM(AZ19:AZ21) -> 2 | BA22: =SUM(AY22:AZ22) -> 170 | BB22: =(BA22+1)/(AH22+1) -> 0.34337349
E23: =SUM(E3:E22) -> 6675 | F23: =SUM(F3:F22) -> 5062 | G23: =SUM(G3:G22) -> 5042 | H23: =SUM(H3:H22) -> 15 | I23: =SUM(I3:I22) -> 5 | J23: =SUM(J3:J22) -> 8 | K23: =SUM(K3:K22) -> 8 | L23: =SUM(L3:L22) -> 36 | M23: =L23/E23 -> 0.0053932584 | N23: =SUM(N3:N22) -> 1047 | O23: =N23/G23 -> 0.20765569 | P23: =SUM(P3:P22) -> 58 | Q23: =P23/G23 -> 0.011503372 | R23: =SUM(R3:R22) -> 14 | S23: =R23/G23 -> 0.0027766759 | T23: =SUM(T3:T6) -> 0 | U23: =T23/G23 -> 0 | V23: =SUM(V3:V22) -> 0 | W23: =SUM(W3:W22) -> 1129 | AB23: Trial 5
AB24: No clip | AL24: =SUM(AI24:AK24)/AG24 -> #DIV/0! | AO24: =SUM(AM24:AN24)/AH24 -> #DIV/0! | AR24: =(AP24+AQ24)/$AH24 -> #DIV/0! | AU24: =(AS24+AT24)/$AH24 -> #DIV/0! | AX24: =(AV24+AW24)/$AH24 -> #DIV/0! | AY24: =SUM(AM24,AP24,AS24,AV24) -> 0 | AZ24: =SUM(AN24,AQ24,AT24,AW24) -> 0 | BA24: =SUM(AY24:AZ24) -> 0 | BB24: =(BA24+1)/(AH24+1) -> 1
F25: In left and right tables enter data in green fields only, all other data is calculated | AB25: Lower clip | AL25: =SUM(AI25:AK25)/AG25 -> #DIV/0! | AO25: =SUM(AM25:AN25)/AH25 -> #DIV/0! | AR25: =(AP25+AQ25)/$AH25 -> #DIV/0! | AU25: =(AS25+AT25)/$AH25 -> #DIV/0! | AX25: =(AV25+AW25)/$AH25 -> #DIV/0! | AY25: =SUM(AM25,AP25,AS25,AV25) -> 0 | AZ25: =SUM(AN25,AQ25,AT25,AW25) -> 0 | BA25: =SUM(AY25:AZ25) -> 0 | BB25: =(BA25+1)/(AH25+1) -> 1
F26: Do not enter data into blue shaded cells | AB26: Upper clip | AC26: 46000 | AD26: 46001 | AE26: 1 | AF26: 457 | AG26: 448 | AH26: 447 | AI26: 3 | AJ26: 0 | AK26: 0 | AL26: =SUM(AI26:AK26)/AG26 -> 0.0066964286 | AM26: 136 | AN26: 0 | AO26: =SUM(AM26:AN26)/AH26 -> 0.30425056 | AP26: 11 | AQ26: 0 | AR26: =(AP26+AQ26)/$AH26 -> 0.024608501 | AS26: 9 | AT26: 0 | AU26: =(AS26+AT26)/$AH26 -> 0.020134228 | AV26: 0 | AW26: 0 | AX26: =(AV26+AW26)/$AH26 -> 0 | AY26: =SUM(AM26,AP26,AS26,AV26) -> 156 | AZ26: =SUM(AN26,AQ26,AT26,AW26) -> 0 | BA26: =SUM(AY26:AZ26) -> 156 | BB26: =(BA26+1)/(AH26+1) -> 0.35044643
AF27: =SUM(AF24:AF26) -> 457 | AG27: =SUM(AG24:AG26) -> 448 | AH27: =SUM(AH24:AH26) -> 447 | AI27: =SUM(AI24:AI26) -> 3 | AJ27: =SUM(AJ24:AJ26) -> 0 | AK27: =SUM(AK24:AK26) -> 0 | AM27: =SUM(AM24:AM26) -> 136 | AN27: =SUM(AN24:AN26) -> 0 | AP27: =SUM(AP24:AP26) -> 11 | AQ27: =SUM(AQ24:AQ26) -> 0 | AS27: =SUM(AS24:AS26) -> 9 | AT27: =SUM(AT24:AT26) -> 0 | AV27: =SUM(AV24:AV26) -> 0 | AW27: =SUM(AW24:AW26) -> 0 | AY27: =SUM(AY24:AY26) -> 156 | AZ27: =SUM(AZ24:AZ26) -> 0 | BA27: =SUM(AY27:AZ27) -> 156 | BB27: =(BA27+1)/(AH27+1) -> 0.35044643
I28: Avg. Released | J28: Avg. Recaps | K28: Avg. Eff | AB28: Trial 6
I29: =AVERAGE(G3:G14) -> 420.16667 | J29: =AVERAGE(W3:W14) -> 94.083333 | K29: =ROUND((J29+1)/(I29+1),4) -> 0.2258 | AB29: No clip | AL29: =SUM(AI29:AK29)/AG29 -> #DIV/0! | AO29: =SUM(AM29:AN29)/AH29 -> #DIV/0! | AR29: =(AP29+AQ29)/$AH29 -> #DIV/0! | AU29: =(AS29+AT29)/$AH29 -> #DIV/0! | AX29: =(AV29+AW29)/$AH29 -> #DIV/0! | AY29: =SUM(AM29,AP29,AS29,AV29) -> 0 | AZ29: =SUM(AN29,AQ29,AT29,AW29) -> 0 | BA29: =SUM(AY29:AZ29) -> 0 | BB29: =(BA29+1)/(AH29+1) -> 1
I30: Rounded season average | AB30: Lower clip | AL30: =SUM(AI30:AK30)/AG30 -> #DIV/0! | AO30: =SUM(AM30:AN30)/AH30 -> #DIV/0! | AR30: =(AP30+AQ30)/$AH30 -> #DIV/0! | AU30: =(AS30+AT30)/$AH30 -> #DIV/0! | AX30: =(AV30+AW30)/$AH30 -> #DIV/0! | AY30: =SUM(AM30,AP30,AS30,AV30) -> 0 | AZ30: =SUM(AN30,AQ30,AT30,AW30) -> 0 | BA30: =SUM(AY30:AZ30) -> 0 | BB30: =(BA30+1)/(AH30+1) -> 1
AB31: Upper clip | AC31: 46003 | AD31: 46004 | AF31: 439 | AG31: 438 | AH31: 437 | AI31: 0 | AJ31: 0 | AK31: 1 | AL31: =SUM(AI31:AK31)/AG31 -> 0.002283105 | AM31: 115 | AN31: 0 | AO31: =SUM(AM31:AN31)/AH31 -> 0.26315789 | AP31: 6 | AQ31: 0 | AR31: =(AP31+AQ31)/$AH31 -> 0.013729977 | AS31: 1 | AT31: 0 | AU31: =(AS31+AT31)/$AH31 -> 0.0022883295 | AV31: 0 | AW31: 0 | AX31: =(AV31+AW31)/$AH31 -> 0 | AY31: =SUM(AM31,AP31,AS31,AV31) -> 122 | AZ31: =SUM(AN31,AQ31,AT31,AW31) -> 0 | BA31: =SUM(AY31:AZ31) -> 122 | BB31: =(BA31+1)/(AH31+1) -> 0.28082192
AF32: =SUM(AF29:AF31) -> 439 | AG32: =SUM(AG29:AG31) -> 438 | AH32: =SUM(AH29:AH31) -> 437 | AI32: =SUM(AI29:AI31) -> 0 | AJ32: =SUM(AJ29:AJ31) -> 0 | AK32: =SUM(AK29:AK31) -> 1 | AM32: =SUM(AM29:AM31) -> 115 | AN32: =SUM(AN29:AN31) -> 0 | AP32: =SUM(AP29:AP31) -> 6 | AQ32: =SUM(AQ29:AQ31) -> 0 | AS32: =SUM(AS29:AS31) -> 1 | AT32: =SUM(AT29:AT31) -> 0 | AV32: =SUM(AV29:AV31) -> 0 | AW32: =SUM(AW29:AW31) -> 0 | AY32: =SUM(AY29:AY31) -> 122 | AZ32: =SUM(AZ29:AZ31) -> 0 | BA32: =SUM(AY32:AZ32) -> 122 | BB32: =(BA32+1)/(AH32+1) -> 0.28082192
AB33: Trial 7
AB34: No clip | AL34: =SUM(AI34:AK34)/AG34 -> #DIV/0! | AO34: =SUM(AM34:AN34)/AH34 -> #DIV/0! | AR34: =(AP34+AQ34)/$AH34 -> #DIV/0! | AU34: =(AS34+AT34)/$AH34 -> #DIV/0! | AX34: =(AV34+AW34)/$AH34 -> #DIV/0! | AY34: =SUM(AM34,AP34,AS34,AV34) -> 0 | AZ34: =SUM(AN34,AQ34,AT34,AW34) -> 0 | BA34: =SUM(AY34:AZ34) -> 0 | BB34: =(BA34+1)/(AH34+1) -> 1
AB35: Lower clip | AL35: =SUM(AI35:AK35)/AG35 -> #DIV/0! | AO35: =SUM(AM35:AN35)/AH35 -> #DIV/0! | AR35: =(AP35+AQ35)/$AH35 -> #DIV/0! | AU35: =(AS35+AT35)/$AH35 -> #DIV/0! | AX35: =(AV35+AW35)/$AH35 -> #DIV/0! | AY35: =SUM(AM35,AP35,AS35,AV35) -> 0 | AZ35: =SUM(AN35,AQ35,AT35,AW35) -> 0 | BA35: =SUM(AY35:AZ35) -> 0 | BB35: =(BA35+1)/(AH35+1) -> 1
AB36: Upper clip | AC36: 46038 | AD36: 46039 | AE36: 1 | AF36: 509 | AG36: 504 | AH36: 503 | AI36: 0 | AJ36: 0 | AL36: =SUM(AI36:AK36)/AG36 -> 0 | AM36: 54 | AN36: 2 | AO36: =SUM(AM36:AN36)/AH36 -> 0.11133201 | AP36: 0 | AQ36: 0 | AR36: =(AP36+AQ36)/$AH36 -> 0 | AS36: 0 | AT36: 0 | AU36: =(AS36+AT36)/$AH36 -> 0 | AV36: 0 | AW36: 0 | AX36: =(AV36+AW36)/$AH36 -> 0 | AY36: =SUM(AM36,AP36,AS36,AV36) -> 54 | AZ36: =SUM(AN36,AQ36,AT36,AW36) -> 2 | BA36: =SUM(AY36:AZ36) -> 56 | BB36: =(BA36+1)/(AH36+1) -> 0.11309524
AF37: =SUM(AF34:AF36) -> 509 | AG37: =SUM(AG34:AG36) -> 504 | AH37: =SUM(AH34:AH36) -> 503 | AI37: =SUM(AI34:AI36) -> 0 | AJ37: =SUM(AJ34:AJ36) -> 0 | AK37: =SUM(AK34:AK36) -> 0 | AM37: =SUM(AM34:AM36) -> 54 | AN37: =SUM(AN34:AN36) -> 2 | AP37: =SUM(AP34:AP36) -> 0 | AQ37: =SUM(AQ34:AQ36) -> 0 | AS37: =SUM(AS34:AS36) -> 0 | AT37: =SUM(AT34:AT36) -> 0 | AV37: =SUM(AV34:AV36) -> 0 | AW37: =SUM(AW34:AW36) -> 0 | AY37: =SUM(AY34:AY36) -> 54 | AZ37: =SUM(AZ34:AZ36) -> 2 | BA37: =SUM(AY37:AZ37) -> 56 | BB37: =(BA37+1)/(AH37+1) -> 0.11309524
AB38: Trial 8
AB39: No clip | AL39: =SUM(AI39:AK39)/AG39 -> #DIV/0! | AO39: =SUM(AM39:AN39)/AH39 -> #DIV/0! | AR39: =(AP39+AQ39)/$AH39 -> #DIV/0! | AU39: =(AS39+AT39)/$AH39 -> #DIV/0! | AX39: =(AV39+AW39)/$AH39 -> #DIV/0! | AY39: =SUM(AM39,AP39,AS39,AV39) -> 0 | AZ39: =SUM(AN39,AQ39,AT39,AW39) -> 0 | BA39: =SUM(AY39:AZ39) -> 0 | BB39: =(BA39+1)/(AH39+1) -> 1
AB40: Lower clip | AL40: =SUM(AI40:AK40)/AG40 -> #DIV/0! | AO40: =SUM(AM40:AN40)/AH40 -> #DIV/0! | AR40: =(AP40+AQ40)/$AH40 -> #DIV/0! | AU40: =(AS40+AT40)/$AH40 -> #DIV/0! | AX40: =(AV40+AW40)/$AH40 -> #DIV/0! | AY40: =SUM(AM40,AP40,AS40,AV40) -> 0 | AZ40: =SUM(AN40,AQ40,AT40,AW40) -> 0 | BA40: =SUM(AY40:AZ40) -> 0 | BB40: =(BA40+1)/(AH40+1) -> 1
...

Sheet LCC CHN 25-26
A1: Lower Clear Creek CHN 2025-2026 | I1: Do not enter data into blue shaded cells | AB1: Lower Clear Creek Chinook Salmon
A2: Trial | B2: Mark date | C2: Release date | D2: Days held | E2: Number held | F2: Number marked | G2: Number released | H2: Pre-mark mortalities | I2: Marking mortalities | J2: Post-mark mortalities | K2: Predation / Trap mortalities | L2: Total mortalities | M2: Percent mortality | N2: Number caught day 1 | O2: Percent caught day 1 | P2: Number caught day 2 | Q2: Percent caught day 2 | R2: Number caught day 3 | S2: Percent caught day 3 | T2: Number caught day 4 | U2: Percent caught day 4 | V2: Total live recaptures | W2: Total recaptured | X2: Bailey's efficiency | Y2: Race | Z2: Origin | AB2: Mark type | AC2: Mark date | AD2: Release date | AE2: Days held | AF2: Number held | AG2: Number marked | AH2: Number released | AI2: Pre-mark mortalities | AJ2: Marking mortalities | AK2: Post-mark mortalities | AL2: Percent mortality | AM2: Number live caught day 1 | AN2: Number mortalities caught day 1 | AO2: Percent caught day 1 | AP2: Number live caught day 2 | AQ2: Number mortalities caught day 2 | AR2: Percent caught day 2 | AS2: Number live caught day 3 | AT2: Number mortalities caught day 3 | AU2: Percent caught day 3 | AV2: Number live caught day 4 | AW2: Number mortalities caught day 4 | AX2: Percent caught day 4 | AY2: Total live recaptured | AZ2: Total mortalities recaptured | BA2: Total recaptured | BB2: Bailey's efficiency | BC2: Race | BD2: Origin
A3: 1 | B3: 45989 | C3: 45990 | D3: 1 | E3: =AF7 -> 506 | F3: =AG7 -> 278 | G3: =AH7 -> 276 | H3: =AI7 -> 2 | I3: =AJ7 -> 0 | J3: =AK7 -> 2 | K3: =AZ7 -> 1 | L3: =SUM(H3:K3) -> 5 | M3: =L3/E3 -> 0.0098814229 | N3: =AM7+AN7 -> 22 | O3: =N3/G3 -> 0.079710145 | P3: =SUM(AO7:AP7) -> 16 | Q3: =P3/G3 -> 0.057971014 | R3: =SUM(AR7:AS7) -> 2 | S3: =R3/G3 -> 0.0072463768 | T3: =SUM(AU7:AV7) -> 0 | U3: =T3/G3 -> 0 | V3: =AX7 -> 0 | W3: =BA7 -> 40 | X3: =(W3+1)/(G3+1) -> 0.14801444 | Y3: SCS | Z3: LCC UCC | AB3: Trial 1
A4: 2 | B4: 45993 | C4: 45994 | D4: 1 | E4: =AF10 -> 608 | F4: =AG10 -> 273 | G4: =AH10 -> 273 | H4: =AI12 -> 0 | I4: =AJ12 -> 0 | J4: =AK12 -> 0 | K4: =AZ12 -> 0 | L4: =SUM(H4:K4) -> 0 | M4: =L4/E4 -> 0 | N4: =AM12+AN12 -> 46 | O4: =N4/G4 -> 0.16849817 | P4: =SUM(AO12:AP12) -> 1 | Q4: =P4/G4 -> 0.0036630037 | R4: =SUM(AR12:AS12) -> 0 | S4: =R4/G4 -> 0 | T4: =SUM(AU12:AV12) -> 0 | U4: =T4/G4 -> 0 | V4: =AX12 -> 0 | W4: =BA12 -> 47 | X4: =(W4+1)/(G4+1) -> 0.17518248 | Y4: SCS | Z4: LCC UCC | AB4: No clip | AL4: =SUM(AI4:AK4)/AG4 -> #DIV/0! | AO4: =SUM(AM4:AN4)/AH4 -> #DIV/0! | AR4: =(AP4+AQ4)/$AH4 -> #DIV/0! | AU4: =(AS4+AT4)/$AH4 -> #DIV/0! | AX4: =(AV4+AW4)/$AH4 -> #DIV/0! | AY4: =SUM(AM4,AP4,AS4,AV4) -> 0 | AZ4: =SUM(AN4,AQ4,AT4,AW4) -> 0 | BA4: =SUM(AY4:AZ4) -> 0 | BB4: =(BA4+1)/(AH4+1) -> 1
A5: 3 | B5: 45996 | C5: 45997 | D5: 1 | E5: =AF17 -> 529 | F5: =AG17 -> 529 | G5: =AH17 -> 528 | H5: =AI17 -> 4 | I5: =AJ17 -> 0 | J5: =AK17 -> 0 | K5: =AZ17 -> 0 | L5: =SUM(H5:K5) -> 4 | M5: =L5/E5 -> 0.0075614367 | N5: =AM17+AN17 -> 28 | O5: =N5/G5 -> 0.053030303 | P5: =SUM(AO17:AP17) -> 5 | Q5: =P5/G5 -> 0.009469697 | R5: =SUM(AR17:AS17) -> 3 | S5: =R5/G5 -> 0.0056818182 | T5: =SUM(AU17:AV17) -> 0 | U5: =T5/G5 -> 0 | V5: =AX17 -> 0 | W5: =BA17 -> 36 | X5: =(W5+1)/(G5+1) -> 0.069943289 | Y5: SCS | Z5: LCC UCC | AB5: Lower clip | AC5: 45989 | AD5: 45990 | AE5: 1 | AF5: 506 | AG5: 278 | AH5: 276 | AI5: 2 | AJ5: 0 | AK5: 2 | AL5: =SUM(AI5:AK5)/AG5 -> 0.014388489 | AM5: 21 | AN5: 1 | AO5: =SUM(AM5:AN5)/AH5 -> 0.079710145 | AP5: 16 | AQ5: 0 | AR5: =(AP5+AQ5)/$AH5 -> 0.057971014 | AS5: 2 | AT5: 0 | AU5: =(AS5+AT5)/$AH5 -> 0.0072463768 | AV5: 0 | AW5: 0 | AX5: =(AV5+AW5)/$AH5 -> 0 | AY5: =SUM(AM5,AP5,AS5,AV5) -> 39 | AZ5: =SUM(AN5,AQ5,AT5,AW5) -> 1 | BA5: =SUM(AY5:AZ5) -> 40 | BB5: =(BA5+1)/(AH5+1) -> 0.14801444 | BC5: SCS | BD5: UCC LCC
A6: 4 | B6: 46000 | C6: 46001 | D6: 1 | E6: =AF22 -> 481 | F6: =AG22 -> 467 | G6: =AH22 -> 465 | H6: =AI22 -> 0 | I6: =AJ22 -> 4 | J6: =AK22 -> 1 | K6: =AZ22 -> 0 | L6: =SUM(H6:K6) -> 5 | M6: =L6/E6 -> 0.01039501 | N6: =AL22+AM22 -> 28 | O6: =N6/G6 -> 0.060215054 | P6: =SUM(AO22:AP22) -> 2 | Q6: =P6/G6 -> 0.0043010753 | R6: =SUM(AR22:AS22) -> 1 | S6: =R6/G6 -> 0.0021505376 | T6: =SUM(AU22:AV22) -> 0 | U6: =T6/G6 -> 0 | V6: =AX22 -> 0 | W6: =BA22 -> 31 | X6: =(W6+1)/(G6+1) -> 0.068669528 | Y6: SCS | Z6: LCC UCC | AB6: Upper clip | AL6: =SUM(AI6:AK6)/AG6 -> #DIV/0! | AO6: =SUM(AM6:AN6)/AH6 -> #DIV/0! | AR6: =(AP6+AQ6)/$AH6 -> #DIV/0! | AU6: =(AS6+AT6)/$AH6 -> #DIV/0! | AX6: =(AV6+AW6)/$AH6 -> #DIV/0! | BB6: =(BA6+1)/(AH6+1) -> 1
A7: 5 | B7: 46003 | C7: 46004 | D7: 1 | E7: =AF27 -> 499 | F7: =AG27 -> 495 | G7: =AH27 -> 496 | H7: =AI27 -> 1 | I7: =AJ27 -> 0 | J7: =AK27 -> 0 | K7: =AZ27 -> 0 | L7: =SUM(H7:K7) -> 1 | M7: =L7/E7 -> 0.002004008 | N7: =AL27+AM27 -> 14 | O7: =N7/G7 -> 0.028225806 | P7: =SUM(AO27:AP27) -> 7 | Q7: =P7/G7 -> 0.014112903 | R7: =SUM(AR27:AS27) -> 0 | S7: =R7/G7 -> 0 | T7: =SUM(AU27:AV27) -> 0 | U7: =T7/G7 -> 0 | V7: =AX27 -> 0 | W7: =BA27 -> 21 | X7: =(W7+1)/(G7+1) -> 0.044265594 | Y7: SCS | Z7: LCC UCC | AF7: =SUM(AF4:AF6) -> 506 | AG7: =SUM(AG4:AG6) -> 278 | AH7: =SUM(AH4:AH6) -> 276 | AI7: =SUM(AI4:AI6) -> 2 | AJ7: =SUM(AJ4:AJ6) -> 0 | AK7: =SUM(AK4:AK6) -> 2 | AM7: =SUM(AM4:AM6) -> 21 | AN7: =SUM(AN4:AN6) -> 1 | AP7: =SUM(AP4:AP6) -> 16 | AQ7: =SUM(AQ4:AQ6) -> 0 | AS7: =SUM(AS4:AS6) -> 2 | AT7: =SUM(AT4:AT6) -> 0 | AV7: =SUM(AV4:AV6) -> 0 | AW7: =SUM(AW4:AW6) -> 0 | AY7: =SUM(AY4:AY6) -> 39 | AZ7: =SUM(AZ4:AZ6) -> 1 | BA7: =SUM(AY7:AZ7) -> 40 | BB7: =(BA7+1)/(AH7+1) -> 0.14801444
A8: 6 | B8: 46038 | C8: 46039 | D8: 1 | E8: =AF32 -> 493 | F8: =AG32 -> 493 | G8: =AH32 -> 503 | H8: =AI32 -> 7 | I8: =AJ32 -> 0 | J8: =AK32 -> 1 | K8: =AZ32 -> 0 | L8: =SUM(H8:K8) -> 8 | M8: =L8/E8 -> 0.016227181 | N8: =AL32+AM32 -> 8 | O8: =N8/G8 -> 0.015904573 | P8: =SUM(AO32:AP32) -> 0 | Q8: =P8/G8 -> 0 | R8: =SUM(AR32:AS32) -> 0 | S8: =R8/G8 -> 0 | T8: =SUM(AU32:AV32) -> 0 | U8: =T8/G8 -> 0 | V8: =AX32 -> 0 | W8: =BA32 -> 8 | X8: =(W8+1)/(G8+1) -> 0.017857143 | Y8: SCS | Z8: LCC | AB8: Trial 2
A9: 7 | B9: 46042 | C9: 46043 | D9: 1 | E9: =AF37 -> 539 | F9: =AG37 -> 535 | G9: =AH37 -> 531 | H9: =AI37 -> 0 | I9: =AJ37 -> 0 | J9: =AK37 -> 3 | K9: =AZ37 -> 0 | L9: =SUM(H9:K9) -> 3 | M9: =L9/E9 -> 0.0055658627 | N9: =AL37+AM37 -> 7 | O9: =N9/G9 -> 0.013182674 | P9: =SUM(AO37:AP37) -> 1 | Q9: =P9/G9 -> 0.0018832392 | R9: =SUM(AR37:AS37) -> 0 | S9: =R9/G9 -> 0 | T9: =SUM(AU37:AV37) -> 0 | U9: =T9/G9 -> 0 | V9: =AX37 -> 0 | W9: =BA37 -> 8 | X9: =(W9+1)/(G9+1) -> 0.016917293 | Y9: SCS | Z9: LCC | AB9: No clip | AL9: =SUM(AI9:AK9)/AG9 -> #DIV/0! | AO9: =SUM(AM9:AN9)/AH9 -> #DIV/0! | AR9: =(AP9+AQ9)/$AH9 -> #DIV/0! | AU9: =(AS9+AT9)/$AH9 -> #DIV/0! | AX9: =(AV9+AW9)/$AH9 -> #DIV/0! | AY9: =SUM(AM9,AP9,AS9,AV9) -> 0 | AZ9: =SUM(AN9,AQ9,AT9,AW9) -> 0 | BA9: =SUM(AY9:AZ9) -> 0 | BB9: =(BA9+1)/(AH9+1) -> 1
A10: 8 | B10: 46045 | C10: 46046 | E10: =AF42 -> 1028 | F10: =AG42 -> 512 | G10: =AH42 -> 503 | H10: =AI42 -> 0 | I10: =AJ42 -> 2 | J10: =AK42 -> 0 | K10: =AZ42 -> 0 | L10: =SUM(H10:K10) -> 2 | M10: =L10/E10 -> 0.0019455253 | N10: =AL42+AM42 -> 7 | O10: =N10/G10 -> 0.013916501 | P10: =SUM(AO42:AP42) -> 0 | Q10: =P10/G10 -> 0 | R10: =SUM(AR42:AS42) -> 0 | S10: =R10/G10 -> 0 | T10: =SUM(AU42:AV42) -> 0 | U10: =T10/G10 -> 0 | V10: =AX42 -> 0 | W10: =BA42 -> 7 | X10: =(W10+1)/(G10+1) -> 0.015873016 | AB10: Lower clip | AC10: 45993 | AD10: 45994 | AE10: 1 | AF10: 608 | AG10: 273 | AH10: 273 | AI10: 0 | AJ10: 0 | AK10: 0 | AL10: =SUM(AI10:AK10)/AG10 -> 0 | AM10: 46 | AN10: 0 | AO10: =SUM(AM10:AN10)/AH10 -> 0.16849817 | AP10: 1 | AQ10: 0 | AR10: =(AP10+AQ10)/$AH10 -> 0.0036630037 | AS10: 0 | AT10: 0 | AU10: =(AS10+AT10)/$AH10 -> 0 | AV10: 0 | AW10: 0 | AX10: =(AV10+AW10)/$AH10 -> 0 | AY10: =SUM(AM10,AP10,AS10,AV10) -> 47 | AZ10: =SUM(AN10,AQ10,AT10,AW10) -> 0 | BA10: =SUM(AY10:AZ10) -> 47 | BB10: =(BA10+1)/(AH10+1) -> 0.17518248 | BC10: SCS | BD10: UCC LCC
A11: 9 | B11: 46052 | C11: 46053 | D11: 2 | E11: =AF47 -> 509 | F11: =AG47 -> 505 | G11: =AH47 -> 503 | H11: =AI47 -> 4 | I11: =AJ47 -> 0 | J11: =AK47 -> 2 | K11: =AZ47 -> 0 | L11: =SUM(H11:K11) -> 6 | M11: =L11/E11 -> 0.011787819 | N11: =AL47+AM47 -> 11 | O11: =N11/G11 -> 0.021868787 | P11: =SUM(AO47:AP47) -> 0 | Q11: =P11/G11 -> 0 | R11: =SUM(AR47:AS47) -> 0 | S11: =R11/G11 -> 0 | T11: =SUM(AU47:AV47) -> 0 | U11: =T11/G11 -> 0 | V11: =AX47 -> 0 | W11: =BA47 -> 11 | X11: =(W11+1)/(G11+1) -> 0.023809524 | Y11: ? | Z11: LCC | AB11: Upper clip | AL11: =SUM(AI11:AK11)/AG11 -> #DIV/0! | AO11: =SUM(AM11:AN11)/AH11 -> #DIV/0! | AR11: =(AP11+AQ11)/$AH11 -> #DIV/0! | AU11: =(AS11+AT11)/$AH11 -> #DIV/0! | AX11: =(AV11+AW11)/$AH11 -> #DIV/0! | AY11: =SUM(AM11,AP11,AS11,AV11) -> 0 | AZ11: =SUM(AN11,AQ11,AT11,AW11) -> 0 | BA11: =SUM(AY11:AZ11) -> 0 | BB11: =(BA11+1)/(AH11+1) -> 1
A12: 10 | B12: 46056 | C12: 46057 | D12: 1 | E12: =AF52 -> 501 | F12: =AG52 -> 499 | G12: =AH52 -> 498 | H12: =AI52 -> 1 | I12: =AJ52 -> 0 | J12: =AK52 -> 1 | K12: =AZ52 -> 0 | L12: =SUM(H12:K12) -> 2 | M12: =L12/E12 -> 0.003992016 | N12: =AL52+AM52 -> 3 | O12: =N12/G12 -> 0.0060240964 | P12: =SUM(AO52:AP52) -> 0 | Q12: =P12/G12 -> 0 | R12: =SUM(AR52:AS52) -> 3 | S12: =R12/G12 -> 0.0060240964 | T12: =SUM(AU52:AV52) -> 0 | U12: =T12/G12 -> 0 | V12: =AX52 -> 0 | W12: =BA52 -> 6 | X12: =(W12+1)/(G12+1) -> 0.014028056 | Y12: FCS | Z12: LCC | AF12: =SUM(AF9:AF11) -> 608 | AG12: =SUM(AG9:AG11) -> 273 | AH12: =SUM(AH9:AH11) -> 273 | AI12: =SUM(AI9:AI11) -> 0 | AJ12: =SUM(AJ9:AJ11) -> 0 | AK12: =SUM(AK9:AK11) -> 0 | AM12: =SUM(AM9:AM11) -> 46 | AN12: =SUM(AN9:AN11) -> 0 | AP12: =SUM(AP9:AP11) -> 1 | AQ12: =SUM(AQ9:AQ11) -> 0 | AS12: =SUM(AS9:AS11) -> 0 | AT12: =SUM(AT9:AT11) -> 0 | AV12: =SUM(AV9:AV11) -> 0 | AW12: =SUM(AW9:AW11) -> 0 | AY12: =SUM(AY9:AY11) -> 47 | AZ12: =SUM(AZ9:AZ11) -> 0 | BA12: =SUM(AY12:AZ12) -> 47 | BB12: =(BA12+1)/(AH12+1) -> 0.17518248
A13: 11 | B13: 46059 | C13: 46060 | D13: 1 | E13: =AF57 -> 500 | F13: =AG57 -> 498 | G13: =AH57 -> 491 | H13: =AI57 -> 1 | I13: =AJ57 -> 0 | J13: =AK57 -> 5 | K13: =AZ57 -> 0 | L13: =SUM(H13:K13) -> 6 | M13: =L13/E13 -> 0.012 | N13: =AL57+AM57 -> 1 | O13: =N13/G13 -> 0.0020366599 | P13: =SUM(AO57:AP57) -> 1 | Q13: =P13/G13 -> 0.0020366599 | R13: =SUM(AR57:AS57) -> 0 | S13: =R13/G13 -> 0 | T13: =SUM(AU57:AV57) -> 0 | U13: =T13/G13 -> 0 | V13: =AX57 -> 0 | W13: =BA57 -> 2 | X13: =(W13+1)/(G13+1) -> 0.006097561 | Y13: FCS | Z13: LCC | AB13: Trial 3
A14: 12 | B14: 46063 | C14: 46063 | D14: 2 | E14: =AF62 -> 424 | F14: =AG62 -> 424 | G14: =AH62 -> 415 | H14: =AI62 -> 6 | I14: =AJ62 -> 0 | J14: =AK62 -> 0 | K14: =AZ62 -> 0 | L14: =SUM(H14:K14) -> 6 | M14: =L14/E14 -> 0.014150943 | N14: =AL62+AM62 -> 4 | O14: =N14/G14 -> 0.0096385542 | P14: =SUM(AO62:AP62) -> 2 | Q14: =P14/G14 -> 0.0048192771 | R14: =SUM(AR62:AS62) -> 0 | S14: =R14/G14 -> 0 | T14: =SUM(AU62:AV62) -> 0 | U14: =T14/G14 -> 0 | V14: =AX62 -> 0 | W14: =BA62 -> 6 | X14: =(W14+1)/(G14+1) -> 0.016826923 | Y14: FCS | Z14: LCC | AB14: No clip | AL14: =SUM(AI14:AK14)/AG14 -> #DIV/0! | AO14: =SUM(AM14:AN14)/AH14 -> #DIV/0! | AR14: =(AP14+AQ14)/$AH14 -> #DIV/0! | AU14: =(AS14+AT14)/$AH14 -> #DIV/0! | AX14: =(AV14+AW14)/$AH14 -> #DIV/0! | AY14: =SUM(AM14,AP14,AS14,AV14) -> 0 | AZ14: =SUM(AN14,AQ14,AT14,AW14) -> 0 | BA14: =SUM(AY14:AZ14) -> 0 | BB14: =(BA14+1)/(AH14+1) -> 1
A15: 13 | B15: 46063 | C15: 46063 | E15: =AF67 -> 472 | F15: =AG67 -> 472 | G15: =AH67 -> 461 | H15: =AI67 -> 3 | I15: =AJ67 -> 0 | J15: =AK67 -> 0 | K15: =AZ67 -> 0 | L15: =SUM(H15:K15) -> 3 | M15: =L15/E15 -> 0.0063559322 | N15: =AL67+AM67 -> 3 | O15: =N15/G15 -> 0.0065075922 | P15: =SUM(AO67:AP67) -> 2 | Q15: =P15/G15 -> 0.0043383948 | R15: =SUM(AR67:AS67) -> 1 | S15: =R15/G15 -> 0.0021691974 | T15: =SUM(AU67:AV67) -> 0 | U15: =T15/G15 -> 0 | V15: =AX67 -> 0 | W15: =BA67 -> 6 | X15: =(W15+1)/(G15+1) -> 0.015151515 | AB15: Lower clip | AC15: 45996 | AD15: 45997 | AE15: 1 | AF15: 529 | AG15: 529 | AH15: 528 | AI15: 4 | AJ15: 0 | AK15: 0 | AL15: =SUM(AI15:AK15)/AG15 -> 0.0075614367 | AM15: 28 | AN15: 0 | AO15: =SUM(AM15:AN15)/AH15 -> 0.053030303 | AP15: 5 | AQ15: 0 | AR15: =(AP15+AQ15)/$AH15 -> 0.009469697 | AS15: 3 | AT15: 0 | AU15: =(AS15+AT15)/$AH15 -> 0.0056818182 | AV15: 0 | AW15: 0 | AX15: =(AV15+AW15)/$AH15 -> 0 | AY15: =SUM(AM15,AP15,AS15,AV15) -> 36 | AZ15: =SUM(AN15,AQ15,AT15,AW15) -> 0 | BA15: =SUM(AY15:AZ15) -> 36 | BB15: =(BA15+1)/(AH15+1) -> 0.069943289
A16: 14 | B16: 46066 | C16: 46066 | D16: 2 | E16: =AF72 -> 520 | F16: =AG72 -> 510 | G16: =AH72 -> 510 | H16: =AI72 -> 5 | I16: =AJ72 -> 0 | J16: =AK72 -> 0 | K16: =AZ72 -> 0 | L16: =SUM(H16:K16) -> 5 | M16: =L16/E16 -> 0.0096153846 | N16: =AL72+AM72 -> 6 | O16: =N16/G16 -> 0.011764706 | P16: =SUM(AO72:AP72) -> 3 | Q16: =P16/G16 -> 0.0058823529 | R16: =SUM(AR72:AS72) -> 1 | S16: =R16/G16 -> 0.0019607843 | T16: =SUM(AU72:AV72) -> 0 | U16: =T16/G16 -> 0 | V16: =AX72 -> 0 | W16: =BA72 -> 10 | X16: =(W16+1)/(G16+1) -> 0.021526419 | Y16: FCS | Z16: LCC | AB16: Upper clip | AL16: =SUM(AI16:AK16)/AG16 -> #DIV/0! | AO16: =SUM(AM16:AN16)/AH16 -> #DIV/0! | AR16: =(AP16+AQ16)/$AH16 -> #DIV/0! | AU16: =(AS16+AT16)/$AH16 -> #DIV/0! | AX16: =(AV16+AW16)/$AH16 -> #DIV/0! | AY16: =SUM(AM16,AP16,AS16,AV16) -> 0 | AZ16: =SUM(AN16,AQ16,AT16,AW16) -> 0 | BA16: =SUM(AY16:AZ16) -> 0 | BB16: =(BA16+1)/(AH16+1) -> 1
A17: 15 | B17: 46066 | C17: 46066 | D17: 2 | E17: =AF77 -> 520 | F17: =AG77 -> 512 | G17: =AH77 -> 512 | H17: =AI77 -> 1 | I17: =AJ77 -> 0 | J17: =AK77 -> 0 | K17: =AZ77 -> 0 | L17: =SUM(H17:K17) -> 1 | M17: =L17/E17 -> 0.0019230769 | N17: =AL77+AM77 -> 5 | O17: =N17/G17 -> 0.009765625 | P17: =SUM(AO77:AP77) -> 1 | Q17: =P17/G17 -> 0.001953125 | R17: =SUM(AR77:AS77) -> 1 | S17: =R17/G17 -> 0.001953125 | T17: =SUM(AU77:AV77) -> 1 | U17: =T17/G17 -> 0.001953125 | V17: =AX77 -> 0 | W17: =BA77 -> 8 | X17: =(W17+1)/(G17+1) -> 0.01754386 | Y17: FCS | Z17: LCC | AF17: =SUM(AF14:AF16) -> 529 | AG17: =SUM(AG14:AG16) -> 529 | AH17: =SUM(AH14:AH16) -> 528 | AI17: =SUM(AI14:AI16) -> 4 | AJ17: =SUM(AJ14:AJ16) -> 0 | AK17: =SUM(AK14:AK16) -> 0 | AM17: =SUM(AM14:AM16) -> 28 | AN17: =SUM(AN14:AN16) -> 0 | AP17: =SUM(AP14:AP16) -> 5 | AQ17: =SUM(AQ14:AQ16) -> 0 | AS17: =SUM(AS14:AS16) -> 3 | AT17: =SUM(AT14:AT16) -> 0 | AV17: =SUM(AV14:AV16) -> 0 | AW17: =SUM(AW14:AW16) -> 0 | AY17: =SUM(AY14:AY16) -> 36 | AZ17: =SUM(AZ14:AZ16) -> 0 | BA17: =SUM(AY17:AZ17) -> 36 | BB17: =(BA17+1)/(AH17+1) -> 0.069943289
A18: 16 | B18: 46090 | C18: 46091 | D18: 3 | E18: =AF82 -> 123 | F18: =AG82 -> 99 | G18: =AH82 -> 94 | H18: =AI82 -> 0 | I18: =AJ82 -> 0 | J18: =AK82 -> 5 | K18: =AZ82 -> 0 | L18: =SUM(H18:K18) -> 5 | M18: =L18/E18 -> 0.040650407 | N18: =AL82+AM82 -> 5 | O18: =N18/G18 -> 0.053191489 | P18: =SUM(AO82:AP82) -> 2 | Q18: =P18/G18 -> 0.021276596 | R18: =SUM(AR82:AS82) -> 1 | S18: =R18/G18 -> 0.010638298 | T18: =SUM(AU82:AV82) -> 0 | U18: =T18/G18 -> 0 | V18: =AX82 -> 0 | W18: =BA82 -> 8 | X18: =(W18+1)/(G18+1) -> 0.094736842 | Y18: FCS | Z18: LCC | AB18: Trial 4
A19: 17 | D19: 3 | E19: =AF87 -> 0 | F19: =AG87 -> 0 | G19: =AH87 -> 0 | H19: =AI87 -> 0 | I19: =AJ87 -> 0 | J19: =AK887 -> 0 | K19: =AZ87 -> 0 | L19: =SUM(H19:K19) -> 0 | M19: =L19/E19 -> #DIV/0! | N19: =AL87+AM87 -> 0 | O19: =N19/G19 -> #DIV/0! | P19: =SUM(AO87:AP87) -> 0 | Q19: =P19/G19 -> #DIV/0! | R19: =SUM(AR87:AS87) -> 0 | S19: =R19/G19 -> #DIV/0! | T19: =SUM(AU87:AV87) -> 0 | U19: =T19/G19 -> #DIV/0! | V19: =AX87 -> 0 | W19: =BA87 -> 0 | X19: =(W19+1)/(G19+1) -> 1 | AB19: No clip | AL19: =SUM(AI19:AK19)/AG19 -> #DIV/0! | AO19: =SUM(AM19:AN19)/AH19 -> #DIV/0! | AR19: =(AP19+AQ19)/$AH19 -> #DIV/0! | AU19: =(AS19+AT19)/$AH19 -> #DIV/0! | AX19: =(AV19+AW19)/$AH19 -> #DIV/0! | AY19: =SUM(AM19,AP19,AS19,AV19) -> 0 | AZ19: =SUM(AN19,AQ19,AT19,AW19) -> 0 | BA19: =SUM(AY19:AZ19) -> 0 | BB19: =(BA19+1)/(AH19+1) -> 1
A20: 18 | E20: =AF92 -> 0 | F20: =AG92 -> 0 | G20: =AH92 -> 0 | H20: =AI92 -> 0 | I20: =AJ92 -> 0 | J20: =AK92 -> 0 | K20: =AZ92 -> 0 | L20: =SUM(H20:K20) -> 0 | M20: =L20/E20 -> #DIV/0! | N20: =AL92+AM92 -> 0 | O20: =N20/G20 -> #DIV/0! | P20: =SUM(AO92:AP92) -> 0 | Q20: =P20/G20 -> #DIV/0! | R20: =SUM(AR92:AS92) -> 0 | S20: =R20/G20 -> #DIV/0! | T20: =SUM(AU92:AV92) -> 0 | U20: =T20/G20 -> #DIV/0! | V20: =AX92 -> 0 | W20: =BA92 -> 0 | X20: =(W20+1)/(G20+1) -> 1 | AB20: Lower clip | AC20: 46000 | AD20: 46001 | AE20: 1 | AF20: 481 | AG20: 467 | AH20: 465 | AI20: 0 | AJ20: 4 | AK20: 1 | AL20: =SUM(AI20:AK20)/AG20 -> 0.010706638 | AM20: 28 | AN20: 0 | AO20: =SUM(AM20:AN20)/AH20 -> 0.060215054 | AP20: 2 | AQ20: 0 | AR20: =(AP20+AQ20)/$AH20 -> 0.0043010753 | AS20: 1 | AT20: 0 | AU20: =(AS20+AT20)/$AH20 -> 0.0021505376 | AV20: 0 | AW20: 0 | AX20: =(AV20+AW20)/$AH20 -> 0 | AY20: =SUM(AM20,AP20,AS20,AV20) -> 31 | AZ20: =SUM(AN20,AQ20,AT20,AW20) -> 0 | BA20: =SUM(AY20:AZ20) -> 31 | BB20: =(BA20+1)/(AH20+1) -> 0.068669528
A21: 19 | E21: =AF97 -> 0 | F21: =AG97 -> 0 | G21: =AH97 -> 0 | H21: =AI97 -> 0 | I21: =AJ97 -> 0 | J21: =AK97 -> 0 | K21: =AZ97 -> 0 | L21: =SUM(H21:K21) -> 0 | M21: =L21/E21 -> #DIV/0! | N21: =AL97+AM97 -> 0 | O21: =N21/G21 -> #DIV/0! | P21: =SUM(AO97:AP97) -> 0 | Q21: =P21/G21 -> #DIV/0! | R21: =SUM(AR97:AS97) -> 0 | S21: =R21/G21 -> #DIV/0! | T21: =SUM(AU97:AV97) -> 0 | U21: =T21/G21 -> #DIV/0! | V21: =AX97 -> 0 | W21: =AB97 -> 0 | X21: =(W21+1)/(G21+1) -> 1 | AB21: Upper clip | AL21: =SUM(AI21:AK21)/AG21 -> #DIV/0! | AO21: =SUM(AM21:AN21)/AH21 -> #DIV/0! | AR21: =(AP21+AQ21)/$AH21 -> #DIV/0! | AU21: =(AS21+AT21)/$AH21 -> #DIV/0! | AX21: =(AV21+AW21)/$AH21 -> #DIV/0! | AY21: =SUM(AM21,AP21,AS21,AV21) -> 0 | AZ21: =SUM(AN21,AQ21,AT21,AW21) -> 0 | BA21: =SUM(AY21:AZ21) -> 0 | BB21: =(BA21+1)/(AH21+1) -> 1
A22: 20 | E22: =AF102 -> 0 | F22: =AG102 -> 0 | G22: =AH102 -> 0 | H22: =AI102 -> 0 | I22: =AJ102 -> 0 | J22: =AK102 -> 0 | K22: =AZ102 -> 0 | L22: =SUM(H22:K22) -> 0 | M22: =L22/E22 -> #DIV/0! | N22: =AL102+AM102 -> 0 | O22: =N22/G22 -> #DIV/0! | P22: =SUM(AO102:AP102) -> 0 | Q22: =P22/G22 -> #DIV/0! | R22: =SUM(AR102:AS102) -> 0 | S22: =R22/G22 -> #DIV/0! | T22: =SUM(AU102:AV102) -> 0 | U22: =T22/G22 -> #DIV/0! | V22: =AX102 -> 0 | W22: =BA102 -> 0 | X22: =(W22+1)/(G22+1) -> 1 | AF22: =SUM(AF19:AF21) -> 481 | AG22: =SUM(AG19:AG21) -> 467 | AH22: =SUM(AH19:AH21) -> 465 | AI22: =SUM(AI19:AI21) -> 0 | AJ22: =SUM(AJ19:AJ21) -> 4 | AK22: =SUM(AK19:AK21) -> 1 | AM22: =SUM(AM19:AM21) -> 28 | AN22: =SUM(AN19:AN21) -> 0 | AP22: =SUM(AP19:AP21) -> 2 | AQ22: =SUM(AQ19:AQ21) -> 0 | AS22: =SUM(AS19:AS21) -> 1 | AT22: =SUM(AT19:AT21) -> 0 | AV22: =SUM(AV19:AV21) -> 0 | AW22: =SUM(AW19:AW21) -> 0 | AY22: =SUM(AY19:AY21) -> 31 | AZ22: =SUM(AZ19:AZ21) -> 0 | BA22: =SUM(AY22:AZ22) -> 31 | BB22: =(BA22+1)/(AH22+1) -> 0.068669528
E23: =SUM(E3:E22) -> 8252 | F23: =SUM(F3:F22) -> 7101 | G23: =SUM(G3:G22) -> 7059 | H23: =SUM(H3:H22) -> 35 | I23: =SUM(I3:I22) -> 6 | J23: =SUM(J3:J22) -> 20 | K23: =SUM(K3:K22) -> 1 | L23: =SUM(L3:L22) -> 62 | M23: =L23/E23 -> 0.0075133301 | N23: =SUM(N3:N22) -> 198 | O23: =N23/G23 -> 0.028049299 | P23: =SUM(P3:P22) -> 43 | Q23: =P23/G23 -> 0.0060915144 | R23: =SUM(R3:R22) -> 13 | S23: =R23/G23 -> 0.0018416206 | T23: =SUM(T3:T6) -> 0 | U23: =T23/G23 -> 0 | V23: =SUM(V3:V22) -> 0 | W23: =SUM(W3:W22) -> 255 | AB23: Trial 5
AB24: No clip | AL24: =SUM(AI24:AK24)/AG24 -> #DIV/0! | AO24: =SUM(AM24:AN24)/AH24 -> #DIV/0! | AR24: =(AP24+AQ24)/$AH24 -> #DIV/0! | AU24: =(AS24+AT24)/$AH24 -> #DIV/0! | AX24: =(AV24+AW24)/$AH24 -> #DIV/0! | AY24: =SUM(AM24,AP24,AS24,AV24) -> 0 | AZ24: =SUM(AN24,AQ24,AT24,AW24) -> 0 | BA24: =SUM(AY24:AZ24) -> 0 | BB24: =(BA24+1)/(AH24+1) -> 1
F25: In left and right tables enter data in green fields only, all other data is calculated | AB25: Lower clip | AC25: 46003 | AD25: 46004 | AE25: 1 | AF25: 499 | AG25: 495 | AH25: 496 | AI25: 1 | AJ25: 0 | AK25: 0 | AL25: =SUM(AI25:AK25)/AG25 -> 0.002020202 | AM25: 14 | AN25: 0 | AO25: =SUM(AM25:AN25)/AH25 -> 0.028225806 | AP25: 7 | AQ25: 0 | AR25: =(AP25+AQ25)/$AH25 -> 0.014112903 | AS25: 0 | AT25: 0 | AU25: =(AS25+AT25)/$AH25 -> 0 | AV25: 0 | AW25: 0 | AX25: =(AV25+AW25)/$AH25 -> 0 | AY25: =SUM(AM25,AP25,AS25,AV25) -> 21 | AZ25: =SUM(AN25,AQ25,AT25,AW25) -> 0 | BA25: =SUM(AY25:AZ25) -> 21 | BB25: =(BA25+1)/(AH25+1) -> 0.044265594
F26: Do not enter data into blue shaded cells | AB26: Upper clip | AL26: =SUM(AI26:AK26)/AG26 -> #DIV/0! | AO26: =SUM(AM26:AN26)/AH26 -> #DIV/0! | AR26: =(AP26+AQ26)/$AH26 -> #DIV/0! | AU26: =(AS26+AT26)/$AH26 -> #DIV/0! | AX26: =(AV26+AW26)/$AH26 -> #DIV/0! | AY26: =SUM(AM26,AP26,AS26,AV26) -> 0 | AZ26: =SUM(AN26,AQ26,AT26,AW26) -> 0 | BA26: =SUM(AY26:AZ26) -> 0 | BB26: =(BA26+1)/(AH26+1) -> 1
AF27: =SUM(AF24:AF26) -> 499 | AG27: =SUM(AG24:AG26) -> 495 | AH27: =SUM(AH24:AH26) -> 496 | AI27: =SUM(AI24:AI26) -> 1 | AJ27: =SUM(AJ24:AJ26) -> 0 | AK27: =SUM(AK24:AK26) -> 0 | AM27: =SUM(AM24:AM26) -> 14 | AN27: =SUM(AN24:AN26) -> 0 | AP27: =SUM(AP24:AP26) -> 7 | AQ27: =SUM(AQ24:AQ26) -> 0 | AS27: =SUM(AS24:AS26) -> 0 | AT27: =SUM(AT24:AT26) -> 0 | AV27: =SUM(AV24:AV26) -> 0 | AW27: =SUM(AW24:AW26) -> 0 | AY27: =SUM(AY24:AY26) -> 21 | AZ27: =SUM(AZ24:AZ26) -> 0 | BA27: =SUM(AY27:AZ27) -> 21 | BB27: =(BA27+1)/(AH27+1) -> 0.044265594
I28: Avg. Released | J28: Avg. Recaps | K28: Avg. Eff | AB28: Trial 6
I29: =AVERAGE(G3:G18) -> 441.1875 | J29: =AVERAGE(W3:W18) -> 15.9375 | K29: =ROUND((J29+1)/(I29+1),4) -> 0.0383 | AB29: No clip | AL29: =SUM(AI29:AK29)/AG29 -> #DIV/0! | AO29: =SUM(AM29:AN29)/AH29 -> #DIV/0! | AR29: =(AP29+AQ29)/$AH29 -> #DIV/0! | AU29: =(AS29+AT29)/$AH29 -> #DIV/0! | AX29: =(AV29+AW29)/$AH29 -> #DIV/0! | AY29: =SUM(AM29,AP29,AS29,AV29) -> 0 | AZ29: =SUM(AN29,AQ29,AT29,AW29) -> 0 | BA29: =SUM(AY29:AZ29) -> 0 | BB29: =(BA29+1)/(AH29+1) -> 1
I30: Rounded season average | AB30: Lower clip | AC30: 46038 | AD30: 46039 | AE30: 1 | AF30: 493 | AG30: 493 | AH30: 503 | AI30: 7 | AJ30: 0 | AK30: 1 | AL30: =SUM(AI30:AK30)/AG30 -> 0.016227181 | AM30: 8 | AN30: 0 | AO30: =SUM(AM30:AN30)/AH30 -> 0.015904573 | AP30: 0 | AQ30: 0 | AR30: =(AP30+AQ30)/$AH30 -> 0 | AS30: 0 | AT30: 0 | AU30: =(AS30+AT30)/$AH30 -> 0 | AV30: 0 | AW30: 0 | AX30: =(AV30+AW30)/$AH30 -> 0 | AY30: =SUM(AM30,AP30,AS30,AV30) -> 8 | AZ30: =SUM(AN30,AQ30,AT30,AW30) -> 0 | BA30: =SUM(AY30:AZ30) -> 8 | BB30: =(BA30+1)/(AH30+1) -> 0.017857143
AB31: Upper clip | AL31: =SUM(AI31:AK31)/AG31 -> #DIV/0! | AO31: =SUM(AM31:AN31)/AH31 -> #DIV/0! | AR31: =(AP31+AQ31)/$AH31 -> #DIV/0! | AU31: =(AS31+AT31)/$AH31 -> #DIV/0! | AX31: =(AV31+AW31)/$AH31 -> #DIV/0! | AY31: =SUM(AM31,AP31,AS31,AV31) -> 0 | AZ31: =SUM(AN31,AQ31,AT31,AW31) -> 0 | BA31: =SUM(AY31:AZ31) -> 0 | BB31: =(BA31+1)/(AH31+1) -> 1
AF32: =SUM(AF29:AF31) -> 493 | AG32: =SUM(AG29:AG31) -> 493 | AH32: =SUM(AH29:AH31) -> 503 | AI32: =SUM(AI29:AI31) -> 7 | AJ32: =SUM(AJ29:AJ31) -> 0 | AK32: =SUM(AK29:AK31) -> 1 | AM32: =SUM(AM29:AM31) -> 8 | AN32: =SUM(AN29:AN31) -> 0 | AP32: =SUM(AP29:AP31) -> 0 | AQ32: =SUM(AQ29:AQ31) -> 0 | AS32: =SUM(AS29:AS31) -> 0 | AT32: =SUM(AT29:AT31) -> 0 | AV32: =SUM(AV29:AV31) -> 0 | AW32: =SUM(AW29:AW31) -> 0 | AY32: =SUM(AY29:AY31) -> 8 | AZ32: =SUM(AZ29:AZ31) -> 0 | BA32: =SUM(AY32:AZ32) -> 8 | BB32: =(BA32+1)/(AH32+1) -> 0.017857143
AB33: Trial 7
AB34: No clip | AL34: =SUM(AI34:AK34)/AG34 -> #DIV/0! | AO34: =SUM(AM34:AN34)/AH34 -> #DIV/0! | AR34: =(AP34+AQ34)/$AH34 -> #DIV/0! | AU34: =(AS34+AT34)/$AH34 -> #DIV/0! | AX34: =(AV34+AW34)/$AH34 -> #DIV/0! | AY34: =SUM(AM34,AP34,AS34,AV34) -> 0 | AZ34: =SUM(AN34,AQ34,AT34,AW34) -> 0 | BA34: =SUM(AY34:AZ34) -> 0 | BB34: =(BA34+1)/(AH34+1) -> 1
AB35: Lower clip | AC35: 46042 | AD35: 46043 | AE35: 1 | AF35: 539 | AG35: 535 | AH35: 531 | AI35: 0 | AJ35: 0 | AK35: 3 | AL35: =SUM(AI35:AK35)/AG35 -> 0.0056074766 | AM35: 7 | AN35: 0 | AO35: =SUM(AM35:AN35)/AH35 -> 0.013182674 | AP35: 1 | AQ35: 0 | AR35: =(AP35+AQ35)/$AH35 -> 0.0018832392 | AS35: 0 | AT35: 0 | AU35: =(AS35+AT35)/$AH35 -> 0 | AV35: 0 | AW35: 0 | AX35: =(AV35+AW35)/$AH35 -> 0 | AY35: =SUM(AM35,AP35,AS35,AV35) -> 8 | AZ35: =SUM(AN35,AQ35,AT35,AW35) -> 0 | BA35: =SUM(AY35:AZ35) -> 8 | BB35: =(BA35+1)/(AH35+1) -> 0.016917293
AB36: Upper clip | AL36: =SUM(AI36:AK36)/AG36 -> #DIV/0! | AO36: =SUM(AM36:AN36)/AH36 -> #DIV/0! | AR36: =(AP36+AQ36)/$AH36 -> #DIV/0! | AU36: =(AS36+AT36)/$AH36 -> #DIV/0! | AX36: =(AV36+AW36)/$AH36 -> #DIV/0! | AY36: =SUM(AM36,AP36,AS36,AV36) -> 0 | AZ36: =SUM(AN36,AQ36,AT36,AW36) -> 0 | BA36: =SUM(AY36:AZ36) -> 0 | BB36: =(BA36+1)/(AH36+1) -> 1
AF37: =SUM(AF34:AF36) -> 539 | AG37: =SUM(AG34:AG36) -> 535 | AH37: =SUM(AH34:AH36) -> 531 | AI37: =SUM(AI34:AI36) -> 0 | AJ37: =SUM(AJ34:AJ36) -> 0 | AK37: =SUM(AK34:AK36) -> 3 | AM37: =SUM(AM34:AM36) -> 7 | AN37: =SUM(AN34:AN36) -> 0 | AP37: =SUM(AP34:AP36) -> 1 | AQ37: =SUM(AQ34:AQ36) -> 0 | AS37: =SUM(AS34:AS36) -> 0 | AT37: =SUM(AT34:AT36) -> 0 | AV37: =SUM(AV34:AV36) -> 0 | AW37: =SUM(AW34:AW36) -> 0 | AY37: =SUM(AY34:AY36) -> 8 | AZ37: =SUM(AZ34:AZ36) -> 0 | BA37: =SUM(AY37:AZ37) -> 8 | BB37: =(BA37+1)/(AH37+1) -> 0.016917293
AB38: Trial 8
AB39: No clip | AL39: =SUM(AI39:AK39)/AG39 -> #DIV/0! | AO39: =SUM(AM39:AN39)/AH39 -> #DIV/0! | AR39: =(AP39+AQ39)/$AH39 -> #DIV/0! | AU39: =(AS39+AT39)/$AH39 -> #DIV/0! | AX39: =(AV39+AW39)/$AH39 -> #DIV/0! | AY39: =SUM(AM39,AP39,AS39,AV39) -> 0 | AZ39: =SUM(AN39,AQ39,AT39,AW39) -> 0 | BA39: =SUM(AY39:AZ39) -> 0 | BB39: =(BA39+1)/(AH39+1) -> 1
AB40: Lower clip | AC40: 46045 | AD40: 46046 | AE40: 1 | AF40: 1028 | AG40: 512 | AH40: 503 | AI40: 0 | AJ40: 2 | AK40: 0 | AL40: =SUM(AI40:AK40)/AG40 -> 0.00390625 | AM40: 7 | AN40: 0 | AO40: =SUM(AM40:AN40)/AH40 -> 0.013916501 | AP40: 0 | AQ40: 0 | AR40: =(AP40+AQ40)/$AH40 -> 0 | AS40: 0 | AT40: 0 | AU40: =(AS40+AT40)/$AH40 -> 0 | AV40: 0 | AW40: 0 | AX40: =(AV40+AW40)/$AH40 -> 0 | AY40: =SUM(AM40,AP40,AS40,AV40) -> 7 | AZ40: =SUM(AN40,AQ40,AT40,AW40) -> 0 | BA40: =SUM(AY40:AZ40) -> 7 | BB40: =(BA40+1)/(AH40+1) -> 0.015873016
...

Sheet LCC RBT 25-26
A1: Lower Clear Creek Rainbow Trout/steelhead 2025-2026 | K1: Do not enter data into blue shaded cells | AE1: Lower Clear Creek Rainbow Trout/steelhead
A2: Trial | B2: Mark date | C2: Release date | D2: Days held | E2: Number held | F2: Number marked | G2: Number released | H2: Pre-mark mortalities | I2: Marking mortalities | J2: Post-mark mortalities | K2: Predation / Trap mortalities | L2: Total mortalities | M2: Percent mortality | N2: Number live caught day 1 | O2: Number mortalities caught day 1 | P2: Percent caught day 1 | Q2: Number live caught day 2 | R2: Number mortalities caught day 2 | S2: Percent caught day 2 | T2: Number live caught day 3 | U2: Number mortalities caught day 3 | V2: Percent caught day 3 | W2: Number live caught day 4 | X2: Number mortalities caught day 4 | Y2: Percent caught day 4 | Z2: Total live recaptures | AA2: Total mortalities recaptured | AB2: Total recaptured | AC2: Bailey's efficiency | AD2: Origin
A3: 1 | L3: =SUM(H3:K3) -> 0 | M3: =SUM(H3:K3)/F3 -> #DIV/0! | P3: =SUM(N3:O3)/$G3 -> #DIV/0! | S3: =SUM(Q3:R3)/$G3 -> #DIV/0! | V3: =SUM(T3:U3)/$G3 -> #DIV/0! | Y3: =SUM(W3:X3)/$G3 -> #DIV/0! | Z3: =SUM(N3,Q3,T3,W3) -> 0 | AA3: =SUM(O3,R3,U3,X3) -> 0 | AB3: =SUM(Z3:AA3) -> 0 | AC3: =(AB3+1)/(G3+1) -> 1
A4: 2 | L4: =SUM(H4:K4) -> 0 | M4: =SUM(H4:K4)/F4 -> #DIV/0! | P4: =SUM(N4:O4)/$G4 -> #DIV/0! | S4: =SUM(Q4:R4)/$G4 -> #DIV/0! | V4: =SUM(T4:U4)/$G4 -> #DIV/0! | Y4: =SUM(W4:X4)/$G4 -> #DIV/0! | Z4: =SUM(N4,Q4,T4,W4) -> 0 | AA4: =SUM(O4,R4,U4,X4) -> 0 | AB4: =SUM(Z4:AA4) -> 0 | AC4: =(AB4+1)/(G4+1) -> 1
A5: 3 | L5: =SUM(H5:K5) -> 0 | M5: =SUM(H5:K5)/F5 -> #DIV/0! | P5: =SUM(N5:O5)/$G5 -> #DIV/0! | S5: =SUM(Q5:R5)/$G5 -> #DIV/0! | V5: =SUM(T5:U5)/$G5 -> #DIV/0! | Y5: =SUM(W5:X5)/$G5 -> #DIV/0! | Z5: =SUM(N5,Q5,T5,W5) -> 0 | AA5: =SUM(O5,R5,U5,X5) -> 0 | AB5: =SUM(Z5:AA5) -> 0 | AC5: =(AB5+1)/(G5+1) -> 1
A6: 4 | L6: =SUM(H6:K6) -> 0 | M6: =SUM(H6:K6)/F6 -> #DIV/0! | P6: =SUM(N6:O6)/$G6 -> #DIV/0! | S6: =SUM(Q6:R6)/$G6 -> #DIV/0! | V6: =SUM(T6:U6)/$G6 -> #DIV/0! | Y6: =SUM(W6:X6)/$G6 -> #DIV/0! | Z6: =SUM(N6,Q6,T6,W6) -> 0 | AA6: =SUM(O6,R6,U6,X6) -> 0 | AB6: =SUM(Z6:AA6) -> 0 | AC6: =(AB6+1)/(G6+1) -> 1
A7: 5 | L7: =SUM(H7:K7) -> 0 | M7: =SUM(H7:K7)/F7 -> #DIV/0! | P7: =SUM(N7:O7)/$G7 -> #DIV/0! | S7: =SUM(Q7:R7)/$G7 -> #DIV/0! | V7: =SUM(T7:U7)/$G7 -> #DIV/0! | Y7: =SUM(W7:X7)/$G7 -> #DIV/0! | Z7: =SUM(N7,Q7,T7,W7) -> 0 | AA7: =SUM(O7,R7,U7,X7) -> 0 | AB7: =SUM(Z7:AA7) -> 0 | AC7: =(AB7+1)/(G7+1) -> 1
A8: 6 | L8: =SUM(H8:K8) -> 0 | M8: =SUM(H8:K8)/F8 -> #DIV/0! | P8: =SUM(N8:O8)/$G8 -> #DIV/0! | S8: =SUM(Q8:R8)/$G8 -> #DIV/0! | V8: =SUM(T8:U8)/$G8 -> #DIV/0! | Y8: =SUM(W8:X8)/$G8 -> #DIV/0! | Z8: =SUM(N8,Q8,T8,W8) -> 0 | AA8: =SUM(O8,R8,U8,X8) -> 0 | AB8: =SUM(Z8:AA8) -> 0 | AC8: =(AB8+1)/(G8+1) -> 1
A9: 7 | L9: =SUM(H9:K9) -> 0 | M9: =SUM(H9:K9)/F9 -> #DIV/0! | P9: =SUM(N9:O9)/$G9 -> #DIV/0! | S9: =SUM(Q9:R9)/$G9 -> #DIV/0! | V9: =SUM(T9:U9)/$G9 -> #DIV/0! | Y9: =SUM(W9:X9)/$G9 -> #DIV/0! | Z9: =SUM(N9,Q9,T9,W9) -> 0 | AA9: =SUM(O9,R9,U9,X9) -> 0 | AB9: =SUM(Z9:AA9) -> 0 | AC9: =(AB9+1)/(G9+1) -> 1
A10: 8 | L10: =SUM(H10:K10) -> 0 | M10: =SUM(H10:K10)/F10 -> #DIV/0! | P10: =SUM(N10:O10)/$G10 -> #DIV/0! | S10: =SUM(Q10:R10)/$G10 -> #DIV/0! | V10: =SUM(T10:U10)/$G10 -> #DIV/0! | Y10: =SUM(W10:X10)/$G10 -> #DIV/0! | Z10: =SUM(N10,Q10,T10,W10) -> 0 | AA10: =SUM(O10,R10,U10,X10) -> 0 | AB10: =SUM(Z10:AA10) -> 0 | AC10: =(AB10+1)/(G10+1) -> 1
A11: 9 | L11: =SUM(H11:K11) -> 0 | M11: =SUM(H11:K11)/F11 -> #DIV/0! | P11: =SUM(N11:O11)/$G11 -> #DIV/0! | S11: =SUM(Q11:R11)/$G11 -> #DIV/0! | V11: =SUM(T11:U11)/$G11 -> #DIV/0! | Y11: =SUM(W11:X11)/$G11 -> #DIV/0! | Z11: =SUM(N11,Q11,T11,W11) -> 0 | AA11: =SUM(O11,R11,U11,X11) -> 0 | AB11: =SUM(Z11:AA11) -> 0 | AC11: =(AB11+1)/(G11+1) -> 1
